Watching for file changes with StatReloader
"GET / HTTP/1.1" 200 14
"GET /about/ HTTP/1.1" 200 11
D:\GB\HTML CSS\Django\hw1\hw1app\views.py changed, reloading.
Watching for file changes with StatReloader
"GET / HTTP/1.1" 200 9
D:\GB\HTML CSS\Django\hw1\hw1app\views.py changed, reloading.
Watching for file changes with StatReloader
"GET / HTTP/1.1" 200 16
"GET / HTTP/1.1" 200 16
"GET / HTTP/1.1" 200 16
D:\GB\HTML CSS\Django\hw1\hw1app\views.py changed, reloading.
Watching for file changes with StatReloader
"GET / HTTP/1.1" 200 29
D:\GB\HTML CSS\Django\hw1\hw1app\views.py changed, reloading.
Watching for file changes with StatReloader
"GET / HTTP/1.1" 200 23
"GET / HTTP/1.1" 200 23
D:\GB\HTML CSS\Django\hw1\hw1app\views.py changed, reloading.
Watching for file changes with StatReloader
"GET / HTTP/1.1" 200 23
"GET / HTTP/1.1" 200 23
"GET / HTTP/1.1" 200 23
D:\GB\HTML CSS\Django\hw1\hw1app\views.py changed, reloading.
Watching for file changes with StatReloader
D:\GB\HTML CSS\Django\hw1\hw1app\views.py changed, reloading.
Watching for file changes with StatReloader
D:\GB\HTML CSS\Django\hw1\hw1app\views.py changed, reloading.
Watching for file changes with StatReloader
D:\GB\HTML CSS\Django\hw1\hw1app\views.py changed, reloading.
Watching for file changes with StatReloader
D:\GB\HTML CSS\Django\hw1\hw1app\views.py changed, reloading.
Watching for file changes with StatReloader
"GET / HTTP/1.1" 200 90
D:\GB\HTML CSS\Django\hw1\hw1app\views.py changed, reloading.
Watching for file changes with StatReloader
D:\GB\HTML CSS\Django\hw1\hw1app\views.py changed, reloading.
Watching for file changes with StatReloader
"GET / HTTP/1.1" 200 167
"GET / HTTP/1.1" 200 167
Not Found: /<function index at 0x0000024EE09BA840>index.html
"GET /%3Cfunction%20index%20at%200x0000024EE09BA840%3Eindex.html HTTP/1.1" 404 2568
D:\GB\HTML CSS\Django\hw1\hw1app\views.py changed, reloading.
Watching for file changes with StatReloader
"GET / HTTP/1.1" 200 231
D:\GB\HTML CSS\Django\hw1\hw1app\views.py changed, reloading.
Watching for file changes with StatReloader
"GET / HTTP/1.1" 200 234
D:\GB\HTML CSS\Django\hw1\hw1app\views.py changed, reloading.
Watching for file changes with StatReloader
"GET / HTTP/1.1" 200 238
Not Found: /<function index at 0x0000021C8F44B100>index.html
"GET /%3Cfunction%20index%20at%200x0000021C8F44B100%3Eindex.html HTTP/1.1" 404 2568
D:\GB\HTML CSS\Django\hw1\hw1app\views.py changed, reloading.
Watching for file changes with StatReloader
Not Found: /<function index at 0x0000021C8F44B100>index.html
"GET /%3Cfunction%20index%20at%200x0000021C8F44B100%3Eindex.html HTTP/1.1" 404 2568
Internal Server Error: /
Traceback (most recent call last):
  File "D:\GB\HTML CSS\Django\venv\Lib\site-packages\django\core\handlers\exception.py", line 55, in inner
    response = get_response(request)
               ^^^^^^^^^^^^^^^^^^^^^
  File "D:\GB\HTML CSS\Django\venv\Lib\site-packages\django\core\handlers\base.py", line 197, in _get_response
    response = wrapped_callback(request, *callback_args, **callback_kwargs)
               ^^^^^^^^^^^^^^^^^^^^^^^^^^^^^^^^^^^^^^^^^^^^^^^^^^^^^^^^^^^^
  File "D:\GB\HTML CSS\Django\hw1\hw1app\views.py", line 10, in index
    f'<a href="{index()}index.html"> Главная </a>'\
                ^^^^^^^
TypeError: index() missing 1 required positional argument: 'request'
"GET / HTTP/1.1" 500 64564
Not Found: /docs
"GET /docs HTTP/1.1" 404 2414
Internal Server Error: /
Traceback (most recent call last):
  File "D:\GB\HTML CSS\Django\venv\Lib\site-packages\django\core\handlers\exception.py", line 55, in inner
    response = get_response(request)
               ^^^^^^^^^^^^^^^^^^^^^
  File "D:\GB\HTML CSS\Django\venv\Lib\site-packages\django\core\handlers\base.py", line 197, in _get_response
    response = wrapped_callback(request, *callback_args, **callback_kwargs)
               ^^^^^^^^^^^^^^^^^^^^^^^^^^^^^^^^^^^^^^^^^^^^^^^^^^^^^^^^^^^^
  File "D:\GB\HTML CSS\Django\hw1\hw1app\views.py", line 10, in index
    f'<a href="{index()}index.html"> Главная </a>'\
                ^^^^^^^
TypeError: index() missing 1 required positional argument: 'request'
"GET / HTTP/1.1" 500 64701
D:\GB\HTML CSS\Django\hw1\hw1app\views.py changed, reloading.
Watching for file changes with StatReloader
"GET / HTTP/1.1" 200 238
Not Found: /<function index at 0x0000020341E1B100>index.html
"GET /%3Cfunction%20index%20at%200x0000020341E1B100%3Eindex.html HTTP/1.1" 404 2568
D:\GB\HTML CSS\Django\hw1\hw1app\views.py changed, reloading.
Watching for file changes with StatReloader
D:\GB\HTML CSS\Django\hw1\hw1app\views.py changed, reloading.
Watching for file changes with StatReloader
Watching for file changes with StatReloader
D:\GB\HTML CSS\Django\hw1\hw1app\views.py changed, reloading.
Watching for file changes with StatReloader
D:\GB\HTML CSS\Django\hw1\hw1app\views.py changed, reloading.
Watching for file changes with StatReloader
"GET / HTTP/1.1" 200 90
"GET /about/ HTTP/1.1" 200 84
D:\GB\HTML CSS\Django\hw1\hw1\settings.py changed, reloading.
Watching for file changes with StatReloader
Watching for file changes with StatReloader
"GET / HTTP/1.1" 200 90
"GET / HTTP/1.1" 200 90
Not Found: /favicon.ico
"GET /favicon.ico HTTP/1.1" 404 2439
"GET / HTTP/1.1" 200 90
"GET /about HTTP/1.1" 301 0
"GET /about/ HTTP/1.1" 200 84
D:\GB\HTML CSS\Django\hw1\hw1\settings.py changed, reloading.
Watching for file changes with StatReloader
"GET /about/ HTTP/1.1" 200 61
D:\GB\HTML CSS\Django\hw1\hw1app\views.py changed, reloading.
Watching for file changes with StatReloader
Watching for file changes with StatReloader
Invalid HTTP_HOST header: '127.0.0.1:8000'. You may need to add '127.0.0.1' to ALLOWED_HOSTS.
Traceback (most recent call last):
  File "D:\GB\HTML CSS\Django\venv\Lib\site-packages\django\core\handlers\exception.py", line 55, in inner
    response = get_response(request)
               ^^^^^^^^^^^^^^^^^^^^^
  File "D:\GB\HTML CSS\Django\venv\Lib\site-packages\django\utils\deprecation.py", line 133, in __call__
    response = self.process_request(request)
               ^^^^^^^^^^^^^^^^^^^^^^^^^^^^^
  File "D:\GB\HTML CSS\Django\venv\Lib\site-packages\django\middleware\common.py", line 48, in process_request
    host = request.get_host()
           ^^^^^^^^^^^^^^^^^^
  File "D:\GB\HTML CSS\Django\venv\Lib\site-packages\django\http\request.py", line 151, in get_host
    raise DisallowedHost(msg)
django.core.exceptions.DisallowedHost: Invalid HTTP_HOST header: '127.0.0.1:8000'. You may need to add '127.0.0.1' to ALLOWED_HOSTS.
Bad Request: /
"GET / HTTP/1.1" 400 69416
D:\GB\HTML CSS\Django\hw1\hw1\settings.py changed, reloading.
Watching for file changes with StatReloader
"GET / HTTP/1.1" 200 90
"GET /about/ HTTP/1.1" 200 84
"GET /about/ HTTP/1.1" 200 84
"GET / HTTP/1.1" 200 90
"GET / HTTP/1.1" 200 90
"GET / HTTP/1.1" 200 90
"GET / HTTP/1.1" 200 90
"GET /about/ HTTP/1.1" 200 84
Not Found: /cube
"GET /cube HTTP/1.1" 404 2414
Not Found: /number
"GET /number HTTP/1.1" 404 2420
Watching for file changes with StatReloader
Not Found: /les3/game/number/10
"GET /les3/game/number/10 HTTP/1.1" 404 2658
"GET /show_orders/3 HTTP/1.1" 301 0
"GET /show_orders/3/ HTTP/1.1" 200 78
"GET /show_orders/17/ HTTP/1.1" 200 51
"GET /show_orders/17/ HTTP/1.1" 200 51
"GET /show_orders/17/ HTTP/1.1" 200 51
"GET /show_orders/17/ HTTP/1.1" 200 51
"GET /show_orders/17/ HTTP/1.1" 200 85
D:\GB\HTML CSS\Django\hw1\hw1app\views.py changed, reloading.
Watching for file changes with StatReloader
Watching for file changes with StatReloader
D:\GB\HTML CSS\Django\hw1\hw1app\urls.py changed, reloading.
Watching for file changes with StatReloader
"GET /show_orders/17/ HTTP/1.1" 200 317
Not Found: /orders_total/week/
"GET /orders_total/week/ HTTP/1.1" 404 2877
Internal Server Error: /orders_total/17/week/
Traceback (most recent call last):
  File "C:\Users\dara3\AppData\Local\Programs\Python\Python311\Lib\site-packages\django\core\handlers\exception.py", line 55, in inner
    response = get_response(request)
               ^^^^^^^^^^^^^^^^^^^^^
  File "C:\Users\dara3\AppData\Local\Programs\Python\Python311\Lib\site-packages\django\core\handlers\base.py", line 197, in _get_response
    response = wrapped_callback(request, *callback_args, **callback_kwargs)
               ^^^^^^^^^^^^^^^^^^^^^^^^^^^^^^^^^^^^^^^^^^^^^^^^^^^^^^^^^^^^
  File "D:\GB\HTML CSS\Django\hw1\hw1app\views.py", line 43, in orders_total
    orders = Order.orders_by_time_delta(user_id, INTERVALS[interval])
             ^^^^^^^^^^^^^^^^^^^^^^^^^^^^^^^^^^^^^^^^^^^^^^^^^^^^^^^^
  File "D:\GB\HTML CSS\Django\hw1\hw1app\models.py", line 34, in orders_by_time_delta
    today = timezone.now().date()
            ^^^^^^^^^^^^
AttributeError: type object 'datetime.timezone' has no attribute 'now'
"GET /orders_total/17/week/ HTTP/1.1" 500 69301
D:\GB\HTML CSS\Django\hw1\hw1app\models.py changed, reloading.
Watching for file changes with StatReloader
Internal Server Error: /orders_total/17/week/
Traceback (most recent call last):
  File "C:\Users\dara3\AppData\Local\Programs\Python\Python311\Lib\site-packages\django\core\handlers\exception.py", line 55, in inner
    response = get_response(request)
               ^^^^^^^^^^^^^^^^^^^^^
  File "C:\Users\dara3\AppData\Local\Programs\Python\Python311\Lib\site-packages\django\core\handlers\base.py", line 197, in _get_response
    response = wrapped_callback(request, *callback_args, **callback_kwargs)
               ^^^^^^^^^^^^^^^^^^^^^^^^^^^^^^^^^^^^^^^^^^^^^^^^^^^^^^^^^^^^
  File "D:\GB\HTML CSS\Django\hw1\hw1app\views.py", line 43, in orders_total
    orders = Order.orders_by_time_delta(user_id, INTERVALS[interval])
             ^^^^^^^^^^^^^^^^^^^^^^^^^^^^^^^^^^^^^^^^^^^^^^^^^^^^^^^^
  File "D:\GB\HTML CSS\Django\hw1\hw1app\models.py", line 35, in orders_by_time_delta
    orders = Order.objects.filter(register_date__date__range=[today - time_delta, today], client_id=user_id)
             ^^^^^^^^^^^^^^^^^^^^^^^^^^^^^^^^^^^^^^^^^^^^^^^^^^^^^^^^^^^^^^^^^^^^^^^^^^^^^^^^^^^^^^^^^^^^^^^
  File "C:\Users\dara3\AppData\Local\Programs\Python\Python311\Lib\site-packages\django\db\models\manager.py", line 87, in manager_method
    return getattr(self.get_queryset(), name)(*args, **kwargs)
           ^^^^^^^^^^^^^^^^^^^^^^^^^^^^^^^^^^^^^^^^^^^^^^^^^^^
  File "C:\Users\dara3\AppData\Local\Programs\Python\Python311\Lib\site-packages\django\db\models\query.py", line 1476, in filter
    return self._filter_or_exclude(False, args, kwargs)
           ^^^^^^^^^^^^^^^^^^^^^^^^^^^^^^^^^^^^^^^^^^^^
  File "C:\Users\dara3\AppData\Local\Programs\Python\Python311\Lib\site-packages\django\db\models\query.py", line 1494, in _filter_or_exclude
    clone._filter_or_exclude_inplace(negate, args, kwargs)
  File "C:\Users\dara3\AppData\Local\Programs\Python\Python311\Lib\site-packages\django\db\models\query.py", line 1501, in _filter_or_exclude_inplace
    self._query.add_q(Q(*args, **kwargs))
  File "C:\Users\dara3\AppData\Local\Programs\Python\Python311\Lib\site-packages\django\db\models\sql\query.py", line 1613, in add_q
    clause, _ = self._add_q(q_object, self.used_aliases)
                ^^^^^^^^^^^^^^^^^^^^^^^^^^^^^^^^^^^^^^^^
  File "C:\Users\dara3\AppData\Local\Programs\Python\Python311\Lib\site-packages\django\db\models\sql\query.py", line 1645, in _add_q
    child_clause, needed_inner = self.build_filter(
                                 ^^^^^^^^^^^^^^^^^^
  File "C:\Users\dara3\AppData\Local\Programs\Python\Python311\Lib\site-packages\django\db\models\sql\query.py", line 1495, in build_filter
    lookups, parts, reffed_expression = self.solve_lookup_type(arg, summarize)
                                        ^^^^^^^^^^^^^^^^^^^^^^^^^^^^^^^^^^^^^^
  File "C:\Users\dara3\AppData\Local\Programs\Python\Python311\Lib\site-packages\django\db\models\sql\query.py", line 1307, in solve_lookup_type
    _, field, _, lookup_parts = self.names_to_path(lookup_splitted, self.get_meta())
                                ^^^^^^^^^^^^^^^^^^^^^^^^^^^^^^^^^^^^^^^^^^^^^^^^^^^^
  File "C:\Users\dara3\AppData\Local\Programs\Python\Python311\Lib\site-packages\django\db\models\sql\query.py", line 1772, in names_to_path
    raise FieldError(
django.core.exceptions.FieldError: Cannot resolve keyword 'register_date' into field. Choices are: client, client_id, date_ordered, id, products, total_price
"GET /orders_total/17/week/ HTTP/1.1" 500 115900
D:\GB\HTML CSS\Django\hw1\hw1app\models.py changed, reloading.
Watching for file changes with StatReloader
D:\GB\HTML CSS\Django\hw1\hw1app\models.py changed, reloading.
Watching for file changes with StatReloader
"GET / HTTP/1.1" 200 90
"GET / HTTP/1.1" 200 90
"GET /show_orders/17/ HTTP/1.1" 200 317
Not Found: /show
"GET /show HTTP/1.1" 404 2835
Internal Server Error: /orders_total/17/week/
Traceback (most recent call last):
  File "C:\Users\dara3\AppData\Local\Programs\Python\Python311\Lib\site-packages\django\core\handlers\exception.py", line 55, in inner
    response = get_response(request)
               ^^^^^^^^^^^^^^^^^^^^^
  File "C:\Users\dara3\AppData\Local\Programs\Python\Python311\Lib\site-packages\django\core\handlers\base.py", line 197, in _get_response
    response = wrapped_callback(request, *callback_args, **callback_kwargs)
               ^^^^^^^^^^^^^^^^^^^^^^^^^^^^^^^^^^^^^^^^^^^^^^^^^^^^^^^^^^^^
  File "D:\GB\HTML CSS\Django\hw1\hw1app\views.py", line 43, in orders_total
    orders = Order.orders_by_time_delta(user_id, INTERVALS[interval])
             ^^^^^^^^^^^^^^^^^^^^^^^^^^^^^^^^^^^^^^^^^^^^^^^^^^^^^^^^
  File "D:\GB\HTML CSS\Django\hw1\hw1app\models.py", line 37, in orders_by_time_delta
    orders = Order.objects.filter(register_date__date__range=[today - time_delta, today], client_id=user_id)
             ^^^^^^^^^^^^^^^^^^^^^^^^^^^^^^^^^^^^^^^^^^^^^^^^^^^^^^^^^^^^^^^^^^^^^^^^^^^^^^^^^^^^^^^^^^^^^^^
  File "C:\Users\dara3\AppData\Local\Programs\Python\Python311\Lib\site-packages\django\db\models\manager.py", line 87, in manager_method
    return getattr(self.get_queryset(), name)(*args, **kwargs)
           ^^^^^^^^^^^^^^^^^^^^^^^^^^^^^^^^^^^^^^^^^^^^^^^^^^^
  File "C:\Users\dara3\AppData\Local\Programs\Python\Python311\Lib\site-packages\django\db\models\query.py", line 1476, in filter
    return self._filter_or_exclude(False, args, kwargs)
           ^^^^^^^^^^^^^^^^^^^^^^^^^^^^^^^^^^^^^^^^^^^^
  File "C:\Users\dara3\AppData\Local\Programs\Python\Python311\Lib\site-packages\django\db\models\query.py", line 1494, in _filter_or_exclude
    clone._filter_or_exclude_inplace(negate, args, kwargs)
  File "C:\Users\dara3\AppData\Local\Programs\Python\Python311\Lib\site-packages\django\db\models\query.py", line 1501, in _filter_or_exclude_inplace
    self._query.add_q(Q(*args, **kwargs))
  File "C:\Users\dara3\AppData\Local\Programs\Python\Python311\Lib\site-packages\django\db\models\sql\query.py", line 1613, in add_q
    clause, _ = self._add_q(q_object, self.used_aliases)
                ^^^^^^^^^^^^^^^^^^^^^^^^^^^^^^^^^^^^^^^^
  File "C:\Users\dara3\AppData\Local\Programs\Python\Python311\Lib\site-packages\django\db\models\sql\query.py", line 1645, in _add_q
    child_clause, needed_inner = self.build_filter(
                                 ^^^^^^^^^^^^^^^^^^
  File "C:\Users\dara3\AppData\Local\Programs\Python\Python311\Lib\site-packages\django\db\models\sql\query.py", line 1495, in build_filter
    lookups, parts, reffed_expression = self.solve_lookup_type(arg, summarize)
                                        ^^^^^^^^^^^^^^^^^^^^^^^^^^^^^^^^^^^^^^
  File "C:\Users\dara3\AppData\Local\Programs\Python\Python311\Lib\site-packages\django\db\models\sql\query.py", line 1307, in solve_lookup_type
    _, field, _, lookup_parts = self.names_to_path(lookup_splitted, self.get_meta())
                                ^^^^^^^^^^^^^^^^^^^^^^^^^^^^^^^^^^^^^^^^^^^^^^^^^^^^
  File "C:\Users\dara3\AppData\Local\Programs\Python\Python311\Lib\site-packages\django\db\models\sql\query.py", line 1772, in names_to_path
    raise FieldError(
django.core.exceptions.FieldError: Cannot resolve keyword 'register_date' into field. Choices are: client, client_id, date_ordered, id, products, total_price
"GET /orders_total/17/week/ HTTP/1.1" 500 115763
Internal Server Error: /orders_total/17/week/
Traceback (most recent call last):
  File "C:\Users\dara3\AppData\Local\Programs\Python\Python311\Lib\site-packages\django\core\handlers\exception.py", line 55, in inner
    response = get_response(request)
               ^^^^^^^^^^^^^^^^^^^^^
  File "C:\Users\dara3\AppData\Local\Programs\Python\Python311\Lib\site-packages\django\core\handlers\base.py", line 197, in _get_response
    response = wrapped_callback(request, *callback_args, **callback_kwargs)
               ^^^^^^^^^^^^^^^^^^^^^^^^^^^^^^^^^^^^^^^^^^^^^^^^^^^^^^^^^^^^
  File "D:\GB\HTML CSS\Django\hw1\hw1app\views.py", line 43, in orders_total
    orders = Order.orders_by_time_delta(user_id, INTERVALS[interval])
             ^^^^^^^^^^^^^^^^^^^^^^^^^^^^^^^^^^^^^^^^^^^^^^^^^^^^^^^^
  File "D:\GB\HTML CSS\Django\hw1\hw1app\models.py", line 37, in orders_by_time_delta
    orders = Order.objects.filter(register_date__date__range=[today - time_delta, today], client_id=user_id)
             ^^^^^^^^^^^^^^^^^^^^^^^^^^^^^^^^^^^^^^^^^^^^^^^^^^^^^^^^^^^^^^^^^^^^^^^^^^^^^^^^^^^^^^^^^^^^^^^
  File "C:\Users\dara3\AppData\Local\Programs\Python\Python311\Lib\site-packages\django\db\models\manager.py", line 87, in manager_method
    return getattr(self.get_queryset(), name)(*args, **kwargs)
           ^^^^^^^^^^^^^^^^^^^^^^^^^^^^^^^^^^^^^^^^^^^^^^^^^^^
  File "C:\Users\dara3\AppData\Local\Programs\Python\Python311\Lib\site-packages\django\db\models\query.py", line 1476, in filter
    return self._filter_or_exclude(False, args, kwargs)
           ^^^^^^^^^^^^^^^^^^^^^^^^^^^^^^^^^^^^^^^^^^^^
  File "C:\Users\dara3\AppData\Local\Programs\Python\Python311\Lib\site-packages\django\db\models\query.py", line 1494, in _filter_or_exclude
    clone._filter_or_exclude_inplace(negate, args, kwargs)
  File "C:\Users\dara3\AppData\Local\Programs\Python\Python311\Lib\site-packages\django\db\models\query.py", line 1501, in _filter_or_exclude_inplace
    self._query.add_q(Q(*args, **kwargs))
  File "C:\Users\dara3\AppData\Local\Programs\Python\Python311\Lib\site-packages\django\db\models\sql\query.py", line 1613, in add_q
    clause, _ = self._add_q(q_object, self.used_aliases)
                ^^^^^^^^^^^^^^^^^^^^^^^^^^^^^^^^^^^^^^^^
  File "C:\Users\dara3\AppData\Local\Programs\Python\Python311\Lib\site-packages\django\db\models\sql\query.py", line 1645, in _add_q
    child_clause, needed_inner = self.build_filter(
                                 ^^^^^^^^^^^^^^^^^^
  File "C:\Users\dara3\AppData\Local\Programs\Python\Python311\Lib\site-packages\django\db\models\sql\query.py", line 1495, in build_filter
    lookups, parts, reffed_expression = self.solve_lookup_type(arg, summarize)
                                        ^^^^^^^^^^^^^^^^^^^^^^^^^^^^^^^^^^^^^^
  File "C:\Users\dara3\AppData\Local\Programs\Python\Python311\Lib\site-packages\django\db\models\sql\query.py", line 1307, in solve_lookup_type
    _, field, _, lookup_parts = self.names_to_path(lookup_splitted, self.get_meta())
                                ^^^^^^^^^^^^^^^^^^^^^^^^^^^^^^^^^^^^^^^^^^^^^^^^^^^^
  File "C:\Users\dara3\AppData\Local\Programs\Python\Python311\Lib\site-packages\django\db\models\sql\query.py", line 1772, in names_to_path
    raise FieldError(
django.core.exceptions.FieldError: Cannot resolve keyword 'register_date' into field. Choices are: client, client_id, date_ordered, id, products, total_price
"GET /orders_total/17/week/ HTTP/1.1" 500 115900
Internal Server Error: /orders_total/17/week/
Traceback (most recent call last):
  File "C:\Users\dara3\AppData\Local\Programs\Python\Python311\Lib\site-packages\django\core\handlers\exception.py", line 55, in inner
    response = get_response(request)
               ^^^^^^^^^^^^^^^^^^^^^
  File "C:\Users\dara3\AppData\Local\Programs\Python\Python311\Lib\site-packages\django\core\handlers\base.py", line 197, in _get_response
    response = wrapped_callback(request, *callback_args, **callback_kwargs)
               ^^^^^^^^^^^^^^^^^^^^^^^^^^^^^^^^^^^^^^^^^^^^^^^^^^^^^^^^^^^^
  File "D:\GB\HTML CSS\Django\hw1\hw1app\views.py", line 43, in orders_total
    orders = Order.orders_by_time_delta(user_id, INTERVALS[interval])
             ^^^^^^^^^^^^^^^^^^^^^^^^^^^^^^^^^^^^^^^^^^^^^^^^^^^^^^^^
  File "D:\GB\HTML CSS\Django\hw1\hw1app\models.py", line 37, in orders_by_time_delta
    orders = Order.objects.filter(register_date__date__range=[today - time_delta, today], client_id=user_id)
             ^^^^^^^^^^^^^^^^^^^^^^^^^^^^^^^^^^^^^^^^^^^^^^^^^^^^^^^^^^^^^^^^^^^^^^^^^^^^^^^^^^^^^^^^^^^^^^^
  File "C:\Users\dara3\AppData\Local\Programs\Python\Python311\Lib\site-packages\django\db\models\manager.py", line 87, in manager_method
    return getattr(self.get_queryset(), name)(*args, **kwargs)
           ^^^^^^^^^^^^^^^^^^^^^^^^^^^^^^^^^^^^^^^^^^^^^^^^^^^
  File "C:\Users\dara3\AppData\Local\Programs\Python\Python311\Lib\site-packages\django\db\models\query.py", line 1476, in filter
    return self._filter_or_exclude(False, args, kwargs)
           ^^^^^^^^^^^^^^^^^^^^^^^^^^^^^^^^^^^^^^^^^^^^
  File "C:\Users\dara3\AppData\Local\Programs\Python\Python311\Lib\site-packages\django\db\models\query.py", line 1494, in _filter_or_exclude
    clone._filter_or_exclude_inplace(negate, args, kwargs)
  File "C:\Users\dara3\AppData\Local\Programs\Python\Python311\Lib\site-packages\django\db\models\query.py", line 1501, in _filter_or_exclude_inplace
    self._query.add_q(Q(*args, **kwargs))
  File "C:\Users\dara3\AppData\Local\Programs\Python\Python311\Lib\site-packages\django\db\models\sql\query.py", line 1613, in add_q
    clause, _ = self._add_q(q_object, self.used_aliases)
                ^^^^^^^^^^^^^^^^^^^^^^^^^^^^^^^^^^^^^^^^
  File "C:\Users\dara3\AppData\Local\Programs\Python\Python311\Lib\site-packages\django\db\models\sql\query.py", line 1645, in _add_q
    child_clause, needed_inner = self.build_filter(
                                 ^^^^^^^^^^^^^^^^^^
  File "C:\Users\dara3\AppData\Local\Programs\Python\Python311\Lib\site-packages\django\db\models\sql\query.py", line 1495, in build_filter
    lookups, parts, reffed_expression = self.solve_lookup_type(arg, summarize)
                                        ^^^^^^^^^^^^^^^^^^^^^^^^^^^^^^^^^^^^^^
  File "C:\Users\dara3\AppData\Local\Programs\Python\Python311\Lib\site-packages\django\db\models\sql\query.py", line 1307, in solve_lookup_type
    _, field, _, lookup_parts = self.names_to_path(lookup_splitted, self.get_meta())
                                ^^^^^^^^^^^^^^^^^^^^^^^^^^^^^^^^^^^^^^^^^^^^^^^^^^^^
  File "C:\Users\dara3\AppData\Local\Programs\Python\Python311\Lib\site-packages\django\db\models\sql\query.py", line 1772, in names_to_path
    raise FieldError(
django.core.exceptions.FieldError: Cannot resolve keyword 'register_date' into field. Choices are: client, client_id, date_ordered, id, products, total_price
"GET /orders_total/17/week/ HTTP/1.1" 500 115900
D:\GB\HTML CSS\Django\hw1\hw1app\models.py changed, reloading.
Watching for file changes with StatReloader
"GET /orders_total/17/week/ HTTP/1.1" 200 246
Watching for file changes with StatReloader
"GET /orders_total/17/week/ HTTP/1.1" 200 255
Watching for file changes with StatReloader
Not Found: /les3/add_goods
"GET /les3/add_goods HTTP/1.1" 404 3040
"GET /add_goods HTTP/1.1" 301 0
"GET /add_goods/ HTTP/1.1" 200 370
Watching for file changes with StatReloader
"GET /add_goods/ HTTP/1.1" 200 370
"GET /add_goods/ HTTP/1.1" 200 370
Internal Server Error: /add_goods/
Traceback (most recent call last):
  File "D:\GB\HTML CSS\Django\venv\Lib\site-packages\django\core\handlers\exception.py", line 55, in inner
    response = get_response(request)
               ^^^^^^^^^^^^^^^^^^^^^
  File "D:\GB\HTML CSS\Django\venv\Lib\site-packages\django\core\handlers\base.py", line 197, in _get_response
    response = wrapped_callback(request, *callback_args, **callback_kwargs)
               ^^^^^^^^^^^^^^^^^^^^^^^^^^^^^^^^^^^^^^^^^^^^^^^^^^^^^^^^^^^^
  File "D:\GB\HTML CSS\Django\hw1\hw1app\views.py", line 54, in add_goods
    if form.is_valid():
       ^^^^^^^^^^^^^
AttributeError: 'Goods' object has no attribute 'is_valid'
"POST /add_goods/ HTTP/1.1" 500 66341
D:\GB\HTML CSS\Django\hw1\hw1app\views.py changed, reloading.
Watching for file changes with StatReloader
D:\GB\HTML CSS\Django\hw1\hw1app\views.py changed, reloading.
Watching for file changes with StatReloader
"GET /add_goods/ HTTP/1.1" 200 1123
D:\GB\HTML CSS\Django\hw1\hw1app\views.py changed, reloading.
Watching for file changes with StatReloader
"GET /add_goods/ HTTP/1.1" 200 1123
"GET /add_goods/ HTTP/1.1" 200 1123
Internal Server Error: /add_goods/
Traceback (most recent call last):
  File "D:\GB\HTML CSS\Django\venv\Lib\site-packages\django\core\handlers\exception.py", line 55, in inner
    response = get_response(request)
               ^^^^^^^^^^^^^^^^^^^^^
  File "D:\GB\HTML CSS\Django\venv\Lib\site-packages\django\core\handlers\base.py", line 204, in _get_response
    self.check_response(response, callback)
  File "D:\GB\HTML CSS\Django\venv\Lib\site-packages\django\core\handlers\base.py", line 332, in check_response
    raise ValueError(
ValueError: The view hw1app.views.add_goods didn't return an HttpResponse object. It returned None instead.
"POST /add_goods/ HTTP/1.1" 500 67472
D:\GB\HTML CSS\Django\hw1\hw1app\views.py changed, reloading.
Watching for file changes with StatReloader
"GET /add_goods/ HTTP/1.1" 200 1123
Internal Server Error: /add_goods/
Traceback (most recent call last):
  File "D:\GB\HTML CSS\Django\venv\Lib\site-packages\django\core\handlers\exception.py", line 55, in inner
    response = get_response(request)
               ^^^^^^^^^^^^^^^^^^^^^
  File "D:\GB\HTML CSS\Django\venv\Lib\site-packages\django\core\handlers\base.py", line 204, in _get_response
    self.check_response(response, callback)
  File "D:\GB\HTML CSS\Django\venv\Lib\site-packages\django\core\handlers\base.py", line 332, in check_response
    raise ValueError(
ValueError: The view hw1app.views.add_goods didn't return an HttpResponse object. It returned None instead.
"POST /add_goods/ HTTP/1.1" 500 67456
D:\GB\HTML CSS\Django\hw1\hw1app\views.py changed, reloading.
Watching for file changes with StatReloader
D:\GB\HTML CSS\Django\hw1\hw1app\views.py changed, reloading.
Watching for file changes with StatReloader
D:\GB\HTML CSS\Django\hw1\hw1app\views.py changed, reloading.
Watching for file changes with StatReloader
D:\GB\HTML CSS\Django\hw1\hw1app\urls.py changed, reloading.
Watching for file changes with StatReloader
D:\GB\HTML CSS\Django\hw1\hw1app\urls.py changed, reloading.
Watching for file changes with StatReloader
"GET /select_goods/ HTTP/1.1" 200 683
Internal Server Error: /select_goods/
Traceback (most recent call last):
  File "D:\GB\HTML CSS\Django\venv\Lib\site-packages\django\core\handlers\exception.py", line 55, in inner
    response = get_response(request)
               ^^^^^^^^^^^^^^^^^^^^^
  File "D:\GB\HTML CSS\Django\venv\Lib\site-packages\django\core\handlers\base.py", line 197, in _get_response
    response = wrapped_callback(request, *callback_args, **callback_kwargs)
               ^^^^^^^^^^^^^^^^^^^^^^^^^^^^^^^^^^^^^^^^^^^^^^^^^^^^^^^^^^^^
  File "D:\GB\HTML CSS\Django\hw1\hw1app\views.py", line 74, in select_an_action
    select = form.cleaned_data['Название']
             ~~~~~~~~~~~~~~~~~^^^^^^^^^^^^
KeyError: 'Название'
"POST /select_goods/ HTTP/1.1" 500 66223
D:\GB\HTML CSS\Django\hw1\hw1app\views.py changed, reloading.
Watching for file changes with StatReloader
"GET /select_goods/ HTTP/1.1" 200 683
Internal Server Error: /select_goods/
Traceback (most recent call last):
  File "D:\GB\HTML CSS\Django\venv\Lib\site-packages\django\core\handlers\exception.py", line 55, in inner
    response = get_response(request)
               ^^^^^^^^^^^^^^^^^^^^^
  File "D:\GB\HTML CSS\Django\venv\Lib\site-packages\django\core\handlers\base.py", line 197, in _get_response
    response = wrapped_callback(request, *callback_args, **callback_kwargs)
               ^^^^^^^^^^^^^^^^^^^^^^^^^^^^^^^^^^^^^^^^^^^^^^^^^^^^^^^^^^^^
  File "D:\GB\HTML CSS\Django\hw1\hw1app\views.py", line 73, in select_an_action
    select = form.cleaned_data['Название']
             ^^^^^^^^^^^^^^^^^
AttributeError: 'SelectGoods' object has no attribute 'cleaned_data'
"POST /select_goods/ HTTP/1.1" 500 66373
D:\GB\HTML CSS\Django\hw1\hw1app\views.py changed, reloading.
Watching for file changes with StatReloader
Internal Server Error: /select_goods/
Traceback (most recent call last):
  File "D:\GB\HTML CSS\Django\venv\Lib\site-packages\django\core\handlers\exception.py", line 55, in inner
    response = get_response(request)
               ^^^^^^^^^^^^^^^^^^^^^
  File "D:\GB\HTML CSS\Django\venv\Lib\site-packages\django\core\handlers\base.py", line 197, in _get_response
    response = wrapped_callback(request, *callback_args, **callback_kwargs)
               ^^^^^^^^^^^^^^^^^^^^^^^^^^^^^^^^^^^^^^^^^^^^^^^^^^^^^^^^^^^^
  File "D:\GB\HTML CSS\Django\hw1\hw1app\views.py", line 73, in select_an_action
    select = form.cleaned_data['select']
             ^^^^^^^^^^^^^^^^^
AttributeError: 'SelectGoods' object has no attribute 'cleaned_data'
"POST /select_goods/ HTTP/1.1" 500 66353
"GET /select_goods/ HTTP/1.1" 200 683
Internal Server Error: /select_goods/
Traceback (most recent call last):
  File "D:\GB\HTML CSS\Django\venv\Lib\site-packages\django\core\handlers\exception.py", line 55, in inner
    response = get_response(request)
               ^^^^^^^^^^^^^^^^^^^^^
  File "D:\GB\HTML CSS\Django\venv\Lib\site-packages\django\core\handlers\base.py", line 197, in _get_response
    response = wrapped_callback(request, *callback_args, **callback_kwargs)
               ^^^^^^^^^^^^^^^^^^^^^^^^^^^^^^^^^^^^^^^^^^^^^^^^^^^^^^^^^^^^
  File "D:\GB\HTML CSS\Django\hw1\hw1app\views.py", line 73, in select_an_action
    select = form.cleaned_data['select']
             ^^^^^^^^^^^^^^^^^
AttributeError: 'SelectGoods' object has no attribute 'cleaned_data'
"POST /select_goods/ HTTP/1.1" 500 66353
D:\GB\HTML CSS\Django\hw1\hw1app\views.py changed, reloading.
Watching for file changes with StatReloader
Internal Server Error: /select_goods/
Traceback (most recent call last):
  File "D:\GB\HTML CSS\Django\venv\Lib\site-packages\django\core\handlers\exception.py", line 55, in inner
    response = get_response(request)
               ^^^^^^^^^^^^^^^^^^^^^
  File "D:\GB\HTML CSS\Django\venv\Lib\site-packages\django\core\handlers\base.py", line 204, in _get_response
    self.check_response(response, callback)
  File "D:\GB\HTML CSS\Django\venv\Lib\site-packages\django\core\handlers\base.py", line 332, in check_response
    raise ValueError(
ValueError: The view hw1app.views.select_an_action didn't return an HttpResponse object. It returned None instead.
"POST /select_goods/ HTTP/1.1" 500 67019
D:\GB\HTML CSS\Django\hw1\hw1app\views.py changed, reloading.
Watching for file changes with StatReloader
"GET /select_goods/ HTTP/1.1" 200 683
Internal Server Error: /select_goods/
Traceback (most recent call last):
  File "D:\GB\HTML CSS\Django\venv\Lib\site-packages\django\core\handlers\exception.py", line 55, in inner
    response = get_response(request)
               ^^^^^^^^^^^^^^^^^^^^^
  File "D:\GB\HTML CSS\Django\venv\Lib\site-packages\django\core\handlers\base.py", line 204, in _get_response
    self.check_response(response, callback)
  File "D:\GB\HTML CSS\Django\venv\Lib\site-packages\django\core\handlers\base.py", line 332, in check_response
    raise ValueError(
ValueError: The view hw1app.views.select_an_action didn't return an HttpResponse object. It returned None instead.
"POST /select_goods/ HTTP/1.1" 500 67019
D:\GB\HTML CSS\Django\hw1\hw1app\views.py changed, reloading.
Watching for file changes with StatReloader
"GET /select_goods/ HTTP/1.1" 200 683
Internal Server Error: /select_goods/
Traceback (most recent call last):
  File "D:\GB\HTML CSS\Django\venv\Lib\site-packages\django\core\handlers\exception.py", line 55, in inner
    response = get_response(request)
               ^^^^^^^^^^^^^^^^^^^^^
  File "D:\GB\HTML CSS\Django\venv\Lib\site-packages\django\utils\deprecation.py", line 136, in __call__
    response = self.process_response(request, response)
               ^^^^^^^^^^^^^^^^^^^^^^^^^^^^^^^^^^^^^^^^
  File "D:\GB\HTML CSS\Django\venv\Lib\site-packages\django\middleware\clickjacking.py", line 27, in process_response
    if response.get("X-Frame-Options") is not None:
       ^^^^^^^^^^^^
AttributeError: 'str' object has no attribute 'get'
"POST /select_goods/ HTTP/1.1" 500 65464
Internal Server Error: /select_goods/
Traceback (most recent call last):
  File "D:\GB\HTML CSS\Django\venv\Lib\site-packages\django\core\handlers\exception.py", line 55, in inner
    response = get_response(request)
               ^^^^^^^^^^^^^^^^^^^^^
  File "D:\GB\HTML CSS\Django\venv\Lib\site-packages\django\utils\deprecation.py", line 136, in __call__
    response = self.process_response(request, response)
               ^^^^^^^^^^^^^^^^^^^^^^^^^^^^^^^^^^^^^^^^
  File "D:\GB\HTML CSS\Django\venv\Lib\site-packages\django\middleware\clickjacking.py", line 27, in process_response
    if response.get("X-Frame-Options") is not None:
       ^^^^^^^^^^^^
AttributeError: 'str' object has no attribute 'get'
"POST /select_goods/ HTTP/1.1" 500 65464
"POST /select_goods/ HTTP/1.1" 200 1521
"POST /select_goods/ HTTP/1.1" 200 765
Watching for file changes with StatReloader
"GET /select_goods/ HTTP/1.1" 200 683
"POST /select_goods/ HTTP/1.1" 200 1521
"POST /select_goods/ HTTP/1.1" 200 765
"POST /select_goods/ HTTP/1.1" 200 1521
"POST /select_goods/ HTTP/1.1" 200 765
"GET /add_goods/ HTTP/1.1" 200 1123
"POST /add_goods/ HTTP/1.1" 200 1263
"POST /add_goods/ HTTP/1.1" 200 1263
"POST /add_goods/ HTTP/1.1" 200 1263
"POST /add_goods/ HTTP/1.1" 200 1263
"POST /add_goods/ HTTP/1.1" 200 1263
"POST /add_goods/ HTTP/1.1" 200 1263
"POST /add_goods/ HTTP/1.1" 200 1263
"POST /add_goods/ HTTP/1.1" 200 1263
D:\GB\HTML CSS\Django\hw1\hw1app\forms.py changed, reloading.
Watching for file changes with StatReloader
D:\GB\HTML CSS\Django\hw1\hw1app\forms.py changed, reloading.
Watching for file changes with StatReloader
D:\GB\HTML CSS\Django\hw1\hw1app\forms.py changed, reloading.
Watching for file changes with StatReloader
"GET /add_goods/ HTTP/1.1" 200 1163
Internal Server Error: /add_goods/
Traceback (most recent call last):
  File "D:\GB\HTML CSS\Django\venv\Lib\site-packages\django\core\handlers\exception.py", line 55, in inner
    response = get_response(request)
               ^^^^^^^^^^^^^^^^^^^^^
  File "D:\GB\HTML CSS\Django\venv\Lib\site-packages\django\core\handlers\base.py", line 197, in _get_response
    response = wrapped_callback(request, *callback_args, **callback_kwargs)
               ^^^^^^^^^^^^^^^^^^^^^^^^^^^^^^^^^^^^^^^^^^^^^^^^^^^^^^^^^^^^
  File "D:\GB\HTML CSS\Django\hw1\hw1app\views.py", line 57, in add_goods
    title = form.cleaned_data['Название']
            ~~~~~~~~~~~~~~~~~^^^^^^^^^^^^
KeyError: 'Название'
"POST /add_goods/ HTTP/1.1" 500 66891
D:\GB\HTML CSS\Django\hw1\hw1app\views.py changed, reloading.
Watching for file changes with StatReloader
"GET /add_goods/ HTTP/1.1" 200 1163
Internal Server Error: /add_goods/
Traceback (most recent call last):
  File "D:\GB\HTML CSS\Django\venv\Lib\site-packages\django\core\handlers\exception.py", line 55, in inner
    response = get_response(request)
               ^^^^^^^^^^^^^^^^^^^^^
  File "D:\GB\HTML CSS\Django\venv\Lib\site-packages\django\core\handlers\base.py", line 197, in _get_response
    response = wrapped_callback(request, *callback_args, **callback_kwargs)
               ^^^^^^^^^^^^^^^^^^^^^^^^^^^^^^^^^^^^^^^^^^^^^^^^^^^^^^^^^^^^
  File "D:\GB\HTML CSS\Django\hw1\hw1app\views.py", line 62, in add_goods
    good = Goods(title=title, description=description, price=price, quantity=quantity, date_of_add=date_of_add)
           ^^^^^^^^^^^^^^^^^^^^^^^^^^^^^^^^^^^^^^^^^^^^^^^^^^^^^^^^^^^^^^^^^^^^^^^^^^^^^^^^^^^^^^^^^^^^^^^^^^^^
TypeError: BaseForm.__init__() got an unexpected keyword argument 'title'
"POST /add_goods/ HTTP/1.1" 500 68088
D:\GB\HTML CSS\Django\hw1\hw1app\forms.py changed, reloading.
Watching for file changes with StatReloader
D:\GB\HTML CSS\Django\hw1\hw1app\views.py changed, reloading.
Watching for file changes with StatReloader
"GET /add_goods/ HTTP/1.1" 200 1163
Internal Server Error: /add_goods/
Traceback (most recent call last):
  File "D:\GB\HTML CSS\Django\venv\Lib\site-packages\django\db\backends\utils.py", line 105, in _execute
    return self.cursor.execute(sql, params)
           ^^^^^^^^^^^^^^^^^^^^^^^^^^^^^^^^
  File "D:\GB\HTML CSS\Django\venv\Lib\site-packages\django\db\backends\sqlite3\base.py", line 329, in execute
    return super().execute(query, params)
           ^^^^^^^^^^^^^^^^^^^^^^^^^^^^^^
sqlite3.OperationalError: no such table: hw1app_goods

The above exception was the direct cause of the following exception:

Traceback (most recent call last):
  File "D:\GB\HTML CSS\Django\venv\Lib\site-packages\django\core\handlers\exception.py", line 55, in inner
    response = get_response(request)
               ^^^^^^^^^^^^^^^^^^^^^
  File "D:\GB\HTML CSS\Django\venv\Lib\site-packages\django\core\handlers\base.py", line 197, in _get_response
    response = wrapped_callback(request, *callback_args, **callback_kwargs)
               ^^^^^^^^^^^^^^^^^^^^^^^^^^^^^^^^^^^^^^^^^^^^^^^^^^^^^^^^^^^^
  File "D:\GB\HTML CSS\Django\hw1\hw1app\views.py", line 64, in add_goods
    good.save()
  File "D:\GB\HTML CSS\Django\venv\Lib\site-packages\django\db\models\base.py", line 822, in save
    self.save_base(
  File "D:\GB\HTML CSS\Django\venv\Lib\site-packages\django\db\models\base.py", line 909, in save_base
    updated = self._save_table(
              ^^^^^^^^^^^^^^^^^
  File "D:\GB\HTML CSS\Django\venv\Lib\site-packages\django\db\models\base.py", line 1067, in _save_table
    results = self._do_insert(
              ^^^^^^^^^^^^^^^^
  File "D:\GB\HTML CSS\Django\venv\Lib\site-packages\django\db\models\base.py", line 1108, in _do_insert
    return manager._insert(
           ^^^^^^^^^^^^^^^^
  File "D:\GB\HTML CSS\Django\venv\Lib\site-packages\django\db\models\manager.py", line 87, in manager_method
    return getattr(self.get_queryset(), name)(*args, **kwargs)
           ^^^^^^^^^^^^^^^^^^^^^^^^^^^^^^^^^^^^^^^^^^^^^^^^^^^
  File "D:\GB\HTML CSS\Django\venv\Lib\site-packages\django\db\models\query.py", line 1847, in _insert
    return query.get_compiler(using=using).execute_sql(returning_fields)
           ^^^^^^^^^^^^^^^^^^^^^^^^^^^^^^^^^^^^^^^^^^^^^^^^^^^^^^^^^^^^^
  File "D:\GB\HTML CSS\Django\venv\Lib\site-packages\django\db\models\sql\compiler.py", line 1823, in execute_sql
    cursor.execute(sql, params)
  File "D:\GB\HTML CSS\Django\venv\Lib\site-packages\django\db\backends\utils.py", line 122, in execute
    return super().execute(sql, params)
           ^^^^^^^^^^^^^^^^^^^^^^^^^^^^
  File "D:\GB\HTML CSS\Django\venv\Lib\site-packages\django\db\backends\utils.py", line 79, in execute
    return self._execute_with_wrappers(
           ^^^^^^^^^^^^^^^^^^^^^^^^^^^^
  File "D:\GB\HTML CSS\Django\venv\Lib\site-packages\django\db\backends\utils.py", line 92, in _execute_with_wrappers
    return executor(sql, params, many, context)
           ^^^^^^^^^^^^^^^^^^^^^^^^^^^^^^^^^^^^
  File "D:\GB\HTML CSS\Django\venv\Lib\site-packages\django\db\backends\utils.py", line 100, in _execute
    with self.db.wrap_database_errors:
  File "D:\GB\HTML CSS\Django\venv\Lib\site-packages\django\db\utils.py", line 91, in __exit__
    raise dj_exc_value.with_traceback(traceback) from exc_value
  File "D:\GB\HTML CSS\Django\venv\Lib\site-packages\django\db\backends\utils.py", line 105, in _execute
    return self.cursor.execute(sql, params)
           ^^^^^^^^^^^^^^^^^^^^^^^^^^^^^^^^
  File "D:\GB\HTML CSS\Django\venv\Lib\site-packages\django\db\backends\sqlite3\base.py", line 329, in execute
    return super().execute(query, params)
           ^^^^^^^^^^^^^^^^^^^^^^^^^^^^^^
django.db.utils.OperationalError: no such table: hw1app_goods
"POST /add_goods/ HTTP/1.1" 500 148898
Watching for file changes with StatReloader
"GET /add_goods/ HTTP/1.1" 200 1163
"POST /add_goods/ HTTP/1.1" 200 1225
"GET /select_goods/ HTTP/1.1" 200 683
"POST /select_goods/ HTTP/1.1" 200 1542
"POST /select_goods/ HTTP/1.1" 200 765
D:\GB\HTML CSS\Django\hw1\hw1app\views.py changed, reloading.
Watching for file changes with StatReloader
Internal Server Error: /select_goods/
Traceback (most recent call last):
  File "C:\Users\dara3\AppData\Local\Programs\Python\Python311\Lib\site-packages\django\core\handlers\exception.py", line 55, in inner
    response = get_response(request)
               ^^^^^^^^^^^^^^^^^^^^^
  File "C:\Users\dara3\AppData\Local\Programs\Python\Python311\Lib\site-packages\django\core\handlers\base.py", line 197, in _get_response
    response = wrapped_callback(request, *callback_args, **callback_kwargs)
               ^^^^^^^^^^^^^^^^^^^^^^^^^^^^^^^^^^^^^^^^^^^^^^^^^^^^^^^^^^^^
  File "D:\GB\HTML CSS\Django\hw1\hw1app\views.py", line 59, in select_an_action
    select = form.cleaned_data['select']
             ^^^^^^^^^^^^^^^^^
AttributeError: 'SelectGoods' object has no attribute 'cleaned_data'
"POST /select_goods/ HTTP/1.1" 500 65644
"GET /select_goods/ HTTP/1.1" 200 683
Internal Server Error: /select_goods/
Traceback (most recent call last):
  File "C:\Users\dara3\AppData\Local\Programs\Python\Python311\Lib\site-packages\django\core\handlers\exception.py", line 55, in inner
    response = get_response(request)
               ^^^^^^^^^^^^^^^^^^^^^
  File "C:\Users\dara3\AppData\Local\Programs\Python\Python311\Lib\site-packages\django\core\handlers\base.py", line 197, in _get_response
    response = wrapped_callback(request, *callback_args, **callback_kwargs)
               ^^^^^^^^^^^^^^^^^^^^^^^^^^^^^^^^^^^^^^^^^^^^^^^^^^^^^^^^^^^^
  File "D:\GB\HTML CSS\Django\hw1\hw1app\views.py", line 59, in select_an_action
    select = form.cleaned_data['select']
             ^^^^^^^^^^^^^^^^^
AttributeError: 'SelectGoods' object has no attribute 'cleaned_data'
"POST /select_goods/ HTTP/1.1" 500 65094
D:\GB\HTML CSS\Django\hw1\hw1app\views.py changed, reloading.
Watching for file changes with StatReloader
"GET /select_goods/ HTTP/1.1" 200 683
"POST /select_goods/ HTTP/1.1" 200 692
"POST /select_goods/ HTTP/1.1" 200 692
"POST /select_goods/ HTTP/1.1" 200 692
"POST /select_goods/ HTTP/1.1" 200 692
"POST /select_goods/ HTTP/1.1" 200 692
D:\GB\HTML CSS\Django\hw1\hw1app\views.py changed, reloading.
Watching for file changes with StatReloader
"GET /select_goods/ HTTP/1.1" 200 683
"POST /select_goods/ HTTP/1.1" 200 692
"POST /select_goods/ HTTP/1.1" 200 692
"POST /select_goods/ HTTP/1.1" 200 692
D:\GB\HTML CSS\Django\hw1\hw1app\views.py changed, reloading.
Watching for file changes with StatReloader
D:\GB\HTML CSS\Django\hw1\hw1app\views.py changed, reloading.
Watching for file changes with StatReloader
"GET /select_goods/ HTTP/1.1" 200 683
"POST /select_goods/ HTTP/1.1" 200 692
"POST /select_goods/ HTTP/1.1" 200 692
"POST /select_goods/ HTTP/1.1" 200 692
"POST /select_goods/ HTTP/1.1" 200 692
"POST /select_goods/ HTTP/1.1" 200 692
D:\GB\HTML CSS\Django\hw1\hw1app\views.py changed, reloading.
Watching for file changes with StatReloader
"GET /select_goods/ HTTP/1.1" 200 683
"POST /select_goods/ HTTP/1.1" 200 692
D:\GB\HTML CSS\Django\hw1\hw1app\views.py changed, reloading.
Watching for file changes with StatReloader
"GET /select_goods/ HTTP/1.1" 200 683
"GET /select_goods/ HTTP/1.1" 200 683
"POST /select_goods/ HTTP/1.1" 200 692
"POST /select_goods/ HTTP/1.1" 200 692
D:\GB\HTML CSS\Django\hw1\hw1app\views.py changed, reloading.
Watching for file changes with StatReloader
"GET /select_goods/ HTTP/1.1" 200 683
"POST /select_goods/ HTTP/1.1" 200 692
"POST /select_goods/ HTTP/1.1" 200 692
"POST /select_goods/ HTTP/1.1" 200 692
"POST /select_goods/ HTTP/1.1" 200 692
"GET /select_goods/ HTTP/1.1" 200 683
D:\GB\HTML CSS\Django\hw1\hw1app\views.py changed, reloading.
Watching for file changes with StatReloader
Watching for file changes with StatReloader
"GET /select_goods/ HTTP/1.1" 200 683
"POST /select_goods/ HTTP/1.1" 200 692
"POST /select_goods/ HTTP/1.1" 200 692
"POST /select_goods/ HTTP/1.1" 200 692
"GET /add_goods/ HTTP/1.1" 200 1163
"POST /add_goods/ HTTP/1.1" 200 1226
"POST /add_goods/ HTTP/1.1" 200 1226
"POST /add_goods/ HTTP/1.1" 200 1226
"POST /add_goods/ HTTP/1.1" 200 1226
D:\GB\HTML CSS\Django\hw1\hw1app\views.py changed, reloading.
Watching for file changes with StatReloader
"GET /add_goods/ HTTP/1.1" 200 1163
"POST /add_goods/ HTTP/1.1" 200 1163
D:\GB\HTML CSS\Django\hw1\hw1app\views.py changed, reloading.
Watching for file changes with StatReloader
D:\GB\HTML CSS\Django\hw1\hw1app\views.py changed, reloading.
Watching for file changes with StatReloader
D:\GB\HTML CSS\Django\hw1\hw1app\views.py changed, reloading.
Watching for file changes with StatReloader
D:\GB\HTML CSS\Django\hw1\hw1app\views.py changed, reloading.
Watching for file changes with StatReloader
"GET /add_goods/ HTTP/1.1" 200 1163
"GET /add_goods/ HTTP/1.1" 200 1163
"POST /add_goods/ HTTP/1.1" 200 1163
Watching for file changes with StatReloader
"GET /add_goods/ HTTP/1.1" 200 1202
"POST /add_goods/ HTTP/1.1" 200 1206
D:\GB\HTML CSS\Django\hw1\hw1app\views.py changed, reloading.
Watching for file changes with StatReloader
D:\GB\HTML CSS\Django\hw1\hw1app\views.py changed, reloading.
Watching for file changes with StatReloader
D:\GB\HTML CSS\Django\hw1\hw1app\views.py changed, reloading.
Watching for file changes with StatReloader
D:\GB\HTML CSS\Django\hw1\hw1app\urls.py changed, reloading.
Watching for file changes with StatReloader
"GET /del_goods/1 HTTP/1.1" 301 0
"GET /del_goods/1/ HTTP/1.1" 200 378
"POST /del_goods/1/ HTTP/1.1" 200 78
D:\GB\HTML CSS\Django\hw1\hw1app\views.py changed, reloading.
Watching for file changes with StatReloader
Not Found: /del_goods/
"GET /del_goods/ HTTP/1.1" 404 3404
"GET /del_goods/2 HTTP/1.1" 301 0
"GET /del_goods/2/ HTTP/1.1" 200 403
"POST /del_goods/2/ HTTP/1.1" 200 61
D:\GB\HTML CSS\Django\hw1\hw1app\forms.py changed, reloading.
Watching for file changes with StatReloader
Internal Server Error: /del_goods/3/
Traceback (most recent call last):
  File "C:\Users\dara3\AppData\Local\Programs\Python\Python311\Lib\site-packages\django\core\handlers\exception.py", line 55, in inner
    response = get_response(request)
               ^^^^^^^^^^^^^^^^^^^^^
  File "C:\Users\dara3\AppData\Local\Programs\Python\Python311\Lib\site-packages\django\core\handlers\base.py", line 204, in _get_response
    self.check_response(response, callback)
  File "C:\Users\dara3\AppData\Local\Programs\Python\Python311\Lib\site-packages\django\core\handlers\base.py", line 332, in check_response
    raise ValueError(
ValueError: The view hw1app.views.del_goods didn't return an HttpResponse object. It returned None instead.
"GET /del_goods/3/ HTTP/1.1" 500 64907
Not Found: /del_goods
"GET /del_goods HTTP/1.1" 404 3401
D:\GB\HTML CSS\Django\hw1\hw1app\urls.py changed, reloading.
Watching for file changes with StatReloader
"GET /del_goods HTTP/1.1" 301 0
Internal Server Error: /del_goods/
Traceback (most recent call last):
  File "C:\Users\dara3\AppData\Local\Programs\Python\Python311\Lib\site-packages\django\core\handlers\exception.py", line 55, in inner
    response = get_response(request)
               ^^^^^^^^^^^^^^^^^^^^^
  File "C:\Users\dara3\AppData\Local\Programs\Python\Python311\Lib\site-packages\django\core\handlers\base.py", line 197, in _get_response
    response = wrapped_callback(request, *callback_args, **callback_kwargs)
               ^^^^^^^^^^^^^^^^^^^^^^^^^^^^^^^^^^^^^^^^^^^^^^^^^^^^^^^^^^^^
TypeError: del_goods() missing 1 required positional argument: 'good_id'
"GET /del_goods/ HTTP/1.1" 500 60497
D:\GB\HTML CSS\Django\hw1\hw1app\views.py changed, reloading.
Watching for file changes with StatReloader
Internal Server Error: /del_goods/
Traceback (most recent call last):
  File "C:\Users\dara3\AppData\Local\Programs\Python\Python311\Lib\site-packages\django\core\handlers\exception.py", line 55, in inner
    response = get_response(request)
               ^^^^^^^^^^^^^^^^^^^^^
  File "C:\Users\dara3\AppData\Local\Programs\Python\Python311\Lib\site-packages\django\core\handlers\base.py", line 204, in _get_response
    self.check_response(response, callback)
  File "C:\Users\dara3\AppData\Local\Programs\Python\Python311\Lib\site-packages\django\core\handlers\base.py", line 332, in check_response
    raise ValueError(
ValueError: The view hw1app.views.del_goods didn't return an HttpResponse object. It returned None instead.
"GET /del_goods/ HTTP/1.1" 500 65004
D:\GB\HTML CSS\Django\hw1\hw1app\views.py changed, reloading.
Watching for file changes with StatReloader
Internal Server Error: /del_goods/
Traceback (most recent call last):
  File "C:\Users\dara3\AppData\Local\Programs\Python\Python311\Lib\site-packages\django\core\handlers\exception.py", line 55, in inner
    response = get_response(request)
               ^^^^^^^^^^^^^^^^^^^^^
  File "C:\Users\dara3\AppData\Local\Programs\Python\Python311\Lib\site-packages\django\core\handlers\base.py", line 197, in _get_response
    response = wrapped_callback(request, *callback_args, **callback_kwargs)
               ^^^^^^^^^^^^^^^^^^^^^^^^^^^^^^^^^^^^^^^^^^^^^^^^^^^^^^^^^^^^
  File "D:\GB\HTML CSS\Django\hw1\hw1app\views.py", line 100, in del_goods
    return render(request, 'hw1app/del_goods.html', {'message': message})
                                                                ^^^^^^^
UnboundLocalError: cannot access local variable 'message' where it is not associated with a value
"GET /del_goods/ HTTP/1.1" 500 63389
D:\GB\HTML CSS\Django\hw1\hw1app\views.py changed, reloading.
Watching for file changes with StatReloader
Internal Server Error: /del_goods/
Traceback (most recent call last):
  File "C:\Users\dara3\AppData\Local\Programs\Python\Python311\Lib\site-packages\django\core\handlers\exception.py", line 55, in inner
    response = get_response(request)
               ^^^^^^^^^^^^^^^^^^^^^
  File "C:\Users\dara3\AppData\Local\Programs\Python\Python311\Lib\site-packages\django\core\handlers\base.py", line 197, in _get_response
    response = wrapped_callback(request, *callback_args, **callback_kwargs)
               ^^^^^^^^^^^^^^^^^^^^^^^^^^^^^^^^^^^^^^^^^^^^^^^^^^^^^^^^^^^^
  File "D:\GB\HTML CSS\Django\hw1\hw1app\views.py", line 100, in del_goods
    return render(request, 'hw1app/del_goods.html', {'message': message})
                                                                ^^^^^^^
UnboundLocalError: cannot access local variable 'message' where it is not associated with a value
"GET /del_goods/ HTTP/1.1" 500 63380
Internal Server Error: /del_goods/
Traceback (most recent call last):
  File "C:\Users\dara3\AppData\Local\Programs\Python\Python311\Lib\site-packages\django\core\handlers\exception.py", line 55, in inner
    response = get_response(request)
               ^^^^^^^^^^^^^^^^^^^^^
  File "C:\Users\dara3\AppData\Local\Programs\Python\Python311\Lib\site-packages\django\core\handlers\base.py", line 197, in _get_response
    response = wrapped_callback(request, *callback_args, **callback_kwargs)
               ^^^^^^^^^^^^^^^^^^^^^^^^^^^^^^^^^^^^^^^^^^^^^^^^^^^^^^^^^^^^
  File "D:\GB\HTML CSS\Django\hw1\hw1app\views.py", line 100, in del_goods
    return render(request, 'hw1app/del_goods.html', {'message': message})
                                                                ^^^^^^^
UnboundLocalError: cannot access local variable 'message' where it is not associated with a value
"GET /del_goods/ HTTP/1.1" 500 63380
D:\GB\HTML CSS\Django\hw1\hw1app\views.py changed, reloading.
Watching for file changes with StatReloader
Internal Server Error: /del_goods/
Traceback (most recent call last):
  File "C:\Users\dara3\AppData\Local\Programs\Python\Python311\Lib\site-packages\django\core\handlers\exception.py", line 55, in inner
    response = get_response(request)
               ^^^^^^^^^^^^^^^^^^^^^
  File "C:\Users\dara3\AppData\Local\Programs\Python\Python311\Lib\site-packages\django\core\handlers\base.py", line 197, in _get_response
    response = wrapped_callback(request, *callback_args, **callback_kwargs)
               ^^^^^^^^^^^^^^^^^^^^^^^^^^^^^^^^^^^^^^^^^^^^^^^^^^^^^^^^^^^^
  File "D:\GB\HTML CSS\Django\hw1\hw1app\views.py", line 99, in del_goods
    message = f'Товар {id} удален'
                       ^^
UnboundLocalError: cannot access local variable 'id' where it is not associated with a value
"GET /del_goods/ HTTP/1.1" 500 63519
D:\GB\HTML CSS\Django\hw1\hw1app\views.py changed, reloading.
Watching for file changes with StatReloader
Internal Server Error: /del_goods/
Traceback (most recent call last):
  File "C:\Users\dara3\AppData\Local\Programs\Python\Python311\Lib\site-packages\django\core\handlers\exception.py", line 55, in inner
    response = get_response(request)
               ^^^^^^^^^^^^^^^^^^^^^
  File "C:\Users\dara3\AppData\Local\Programs\Python\Python311\Lib\site-packages\django\core\handlers\base.py", line 197, in _get_response
    response = wrapped_callback(request, *callback_args, **callback_kwargs)
               ^^^^^^^^^^^^^^^^^^^^^^^^^^^^^^^^^^^^^^^^^^^^^^^^^^^^^^^^^^^^
  File "D:\GB\HTML CSS\Django\hw1\hw1app\views.py", line 99, in del_goods
    message = f'Товар {good} удален'
                       ^^^^
UnboundLocalError: cannot access local variable 'good' where it is not associated with a value
"GET /del_goods/ HTTP/1.1" 500 63535
D:\GB\HTML CSS\Django\hw1\hw1app\views.py changed, reloading.
Watching for file changes with StatReloader
"GET /del_goods/ HTTP/1.1" 200 401
D:\GB\HTML CSS\Django\hw1\hw1app\views.py changed, reloading.
Watching for file changes with StatReloader
"GET /del_goods/ HTTP/1.1" 200 405
D:\GB\HTML CSS\Django\hw1\hw1app\views.py changed, reloading.
Watching for file changes with StatReloader
"GET /del_goods/ HTTP/1.1" 200 528
Internal Server Error: /del_goods/
Traceback (most recent call last):
  File "C:\Users\dara3\AppData\Local\Programs\Python\Python311\Lib\site-packages\django\core\handlers\exception.py", line 55, in inner
    response = get_response(request)
               ^^^^^^^^^^^^^^^^^^^^^
  File "C:\Users\dara3\AppData\Local\Programs\Python\Python311\Lib\site-packages\django\core\handlers\base.py", line 197, in _get_response
    response = wrapped_callback(request, *callback_args, **callback_kwargs)
               ^^^^^^^^^^^^^^^^^^^^^^^^^^^^^^^^^^^^^^^^^^^^^^^^^^^^^^^^^^^^
  File "D:\GB\HTML CSS\Django\hw1\hw1app\views.py", line 93, in del_goods
    good = Goods.objects.filter(id).first()
                                ^^
UnboundLocalError: cannot access local variable 'id' where it is not associated with a value
"POST /del_goods/ HTTP/1.1" 500 65255
D:\GB\HTML CSS\Django\hw1\hw1app\views.py changed, reloading.
Watching for file changes with StatReloader
"GET /del_goods/ HTTP/1.1" 200 528
Internal Server Error: /del_goods/
Traceback (most recent call last):
  File "C:\Users\dara3\AppData\Local\Programs\Python\Python311\Lib\site-packages\django\core\handlers\exception.py", line 55, in inner
    response = get_response(request)
               ^^^^^^^^^^^^^^^^^^^^^
  File "C:\Users\dara3\AppData\Local\Programs\Python\Python311\Lib\site-packages\django\core\handlers\base.py", line 197, in _get_response
    response = wrapped_callback(request, *callback_args, **callback_kwargs)
               ^^^^^^^^^^^^^^^^^^^^^^^^^^^^^^^^^^^^^^^^^^^^^^^^^^^^^^^^^^^^
  File "D:\GB\HTML CSS\Django\hw1\hw1app\views.py", line 93, in del_goods
    good = Goods.objects.filter(id=id).first()
                                   ^^
UnboundLocalError: cannot access local variable 'id' where it is not associated with a value
"POST /del_goods/ HTTP/1.1" 500 65267
D:\GB\HTML CSS\Django\hw1\hw1app\views.py changed, reloading.
Watching for file changes with StatReloader
"GET /del_goods/ HTTP/1.1" 200 528
Internal Server Error: /del_goods/
Traceback (most recent call last):
  File "C:\Users\dara3\AppData\Local\Programs\Python\Python311\Lib\site-packages\django\core\handlers\exception.py", line 55, in inner
    response = get_response(request)
               ^^^^^^^^^^^^^^^^^^^^^
  File "C:\Users\dara3\AppData\Local\Programs\Python\Python311\Lib\site-packages\django\core\handlers\base.py", line 197, in _get_response
    response = wrapped_callback(request, *callback_args, **callback_kwargs)
               ^^^^^^^^^^^^^^^^^^^^^^^^^^^^^^^^^^^^^^^^^^^^^^^^^^^^^^^^^^^^
  File "D:\GB\HTML CSS\Django\hw1\hw1app\views.py", line 93, in del_goods
    good = Goods.objects.filter(id=id).first()
                                   ^^
UnboundLocalError: cannot access local variable 'id' where it is not associated with a value
"POST /del_goods/ HTTP/1.1" 500 65280
D:\GB\HTML CSS\Django\hw1\hw1app\views.py changed, reloading.
Watching for file changes with StatReloader
"GET /del_goods/ HTTP/1.1" 200 528
Internal Server Error: /del_goods/
Traceback (most recent call last):
  File "C:\Users\dara3\AppData\Local\Programs\Python\Python311\Lib\site-packages\django\core\handlers\exception.py", line 55, in inner
    response = get_response(request)
               ^^^^^^^^^^^^^^^^^^^^^
  File "C:\Users\dara3\AppData\Local\Programs\Python\Python311\Lib\site-packages\django\core\handlers\base.py", line 197, in _get_response
    response = wrapped_callback(request, *callback_args, **callback_kwargs)
               ^^^^^^^^^^^^^^^^^^^^^^^^^^^^^^^^^^^^^^^^^^^^^^^^^^^^^^^^^^^^
  File "D:\GB\HTML CSS\Django\hw1\hw1app\views.py", line 93, in del_goods
    good = Goods.objects.filter(id=id).first()
                                   ^^
UnboundLocalError: cannot access local variable 'id' where it is not associated with a value
"POST /del_goods/ HTTP/1.1" 500 65283
D:\GB\HTML CSS\Django\hw1\hw1app\views.py changed, reloading.
Watching for file changes with StatReloader
D:\GB\HTML CSS\Django\hw1\hw1app\views.py changed, reloading.
Watching for file changes with StatReloader
Internal Server Error: /del_goods/
Traceback (most recent call last):
  File "C:\Users\dara3\AppData\Local\Programs\Python\Python311\Lib\site-packages\django\core\handlers\exception.py", line 55, in inner
    response = get_response(request)
               ^^^^^^^^^^^^^^^^^^^^^
  File "C:\Users\dara3\AppData\Local\Programs\Python\Python311\Lib\site-packages\django\core\handlers\base.py", line 197, in _get_response
    response = wrapped_callback(request, *callback_args, **callback_kwargs)
               ^^^^^^^^^^^^^^^^^^^^^^^^^^^^^^^^^^^^^^^^^^^^^^^^^^^^^^^^^^^^
TypeError: del_goods() missing 1 required positional argument: 'parser'
"GET /del_goods/ HTTP/1.1" 500 60356
D:\GB\HTML CSS\Django\hw1\hw1app\views.py changed, reloading.
Watching for file changes with StatReloader
"GET /del_goods/ HTTP/1.1" 200 528
Internal Server Error: /del_goods/
Traceback (most recent call last):
  File "C:\Users\dara3\AppData\Local\Programs\Python\Python311\Lib\site-packages\django\core\handlers\exception.py", line 55, in inner
    response = get_response(request)
               ^^^^^^^^^^^^^^^^^^^^^
  File "C:\Users\dara3\AppData\Local\Programs\Python\Python311\Lib\site-packages\django\core\handlers\base.py", line 197, in _get_response
    response = wrapped_callback(request, *callback_args, **callback_kwargs)
               ^^^^^^^^^^^^^^^^^^^^^^^^^^^^^^^^^^^^^^^^^^^^^^^^^^^^^^^^^^^^
  File "D:\GB\HTML CSS\Django\hw1\hw1app\views.py", line 96, in del_goods
    pk = form.cleaned_data['pk']
         ~~~~~~~~~~~~~~~~~^^^^^^
KeyError: 'pk'
"POST /del_goods/ HTTP/1.1" 500 65008
D:\GB\HTML CSS\Django\hw1\hw1app\views.py changed, reloading.
Watching for file changes with StatReloader
"GET /del_goods/ HTTP/1.1" 200 528
Internal Server Error: /del_goods/
Traceback (most recent call last):
  File "C:\Users\dara3\AppData\Local\Programs\Python\Python311\Lib\site-packages\django\core\handlers\exception.py", line 55, in inner
    response = get_response(request)
               ^^^^^^^^^^^^^^^^^^^^^
  File "C:\Users\dara3\AppData\Local\Programs\Python\Python311\Lib\site-packages\django\core\handlers\base.py", line 197, in _get_response
    response = wrapped_callback(request, *callback_args, **callback_kwargs)
               ^^^^^^^^^^^^^^^^^^^^^^^^^^^^^^^^^^^^^^^^^^^^^^^^^^^^^^^^^^^^
  File "D:\GB\HTML CSS\Django\hw1\hw1app\views.py", line 96, in del_goods
    pk = form.cleaned_data['pk']
         ~~~~~~~~~~~~~~~~~^^^^^^
KeyError: 'pk'
"POST /del_goods/ HTTP/1.1" 500 64999
D:\GB\HTML CSS\Django\hw1\hw1app\views.py changed, reloading.
Watching for file changes with StatReloader
Internal Server Error: /del_good/
Traceback (most recent call last):
  File "C:\Users\dara3\AppData\Local\Programs\Python\Python311\Lib\site-packages\django\core\handlers\exception.py", line 55, in inner
    response = get_response(request)
               ^^^^^^^^^^^^^^^^^^^^^
  File "C:\Users\dara3\AppData\Local\Programs\Python\Python311\Lib\site-packages\django\core\handlers\base.py", line 197, in _get_response
    response = wrapped_callback(request, *callback_args, **callback_kwargs)
               ^^^^^^^^^^^^^^^^^^^^^^^^^^^^^^^^^^^^^^^^^^^^^^^^^^^^^^^^^^^^
TypeError: del_good() missing 1 required positional argument: 'good_id'
"GET /del_good/ HTTP/1.1" 500 60344
D:\GB\HTML CSS\Django\hw1\hw1app\views.py changed, reloading.
Watching for file changes with StatReloader
Internal Server Error: /del_good/
Traceback (most recent call last):
  File "C:\Users\dara3\AppData\Local\Programs\Python\Python311\Lib\site-packages\django\core\handlers\exception.py", line 55, in inner
    response = get_response(request)
               ^^^^^^^^^^^^^^^^^^^^^
  File "C:\Users\dara3\AppData\Local\Programs\Python\Python311\Lib\site-packages\django\core\handlers\base.py", line 197, in _get_response
    response = wrapped_callback(request, *callback_args, **callback_kwargs)
               ^^^^^^^^^^^^^^^^^^^^^^^^^^^^^^^^^^^^^^^^^^^^^^^^^^^^^^^^^^^^
TypeError: del_good() missing 1 required positional argument: 'good_id'
"GET /del_good/ HTTP/1.1" 500 60481
Internal Server Error: /del_good/
Traceback (most recent call last):
  File "C:\Users\dara3\AppData\Local\Programs\Python\Python311\Lib\site-packages\django\core\handlers\exception.py", line 55, in inner
    response = get_response(request)
               ^^^^^^^^^^^^^^^^^^^^^
  File "C:\Users\dara3\AppData\Local\Programs\Python\Python311\Lib\site-packages\django\core\handlers\base.py", line 197, in _get_response
    response = wrapped_callback(request, *callback_args, **callback_kwargs)
               ^^^^^^^^^^^^^^^^^^^^^^^^^^^^^^^^^^^^^^^^^^^^^^^^^^^^^^^^^^^^
TypeError: del_good() missing 1 required positional argument: 'good_id'
"GET /del_good/ HTTP/1.1" 500 60481
Internal Server Error: /del_good/
Traceback (most recent call last):
  File "C:\Users\dara3\AppData\Local\Programs\Python\Python311\Lib\site-packages\django\core\handlers\exception.py", line 55, in inner
    response = get_response(request)
               ^^^^^^^^^^^^^^^^^^^^^
  File "C:\Users\dara3\AppData\Local\Programs\Python\Python311\Lib\site-packages\django\core\handlers\base.py", line 197, in _get_response
    response = wrapped_callback(request, *callback_args, **callback_kwargs)
               ^^^^^^^^^^^^^^^^^^^^^^^^^^^^^^^^^^^^^^^^^^^^^^^^^^^^^^^^^^^^
TypeError: del_good() missing 1 required positional argument: 'good_id'
"GET /del_good/ HTTP/1.1" 500 60481
D:\GB\HTML CSS\Django\hw1\hw1app\views.py changed, reloading.
Watching for file changes with StatReloader
Internal Server Error: /del_good/
Traceback (most recent call last):
  File "C:\Users\dara3\AppData\Local\Programs\Python\Python311\Lib\site-packages\django\db\models\fields\__init__.py", line 2117, in get_prep_value
    return int(value)
           ^^^^^^^^^^
TypeError: int() argument must be a string, a bytes-like object or a real number, not 'WSGIRequest'

The above exception was the direct cause of the following exception:

Traceback (most recent call last):
  File "C:\Users\dara3\AppData\Local\Programs\Python\Python311\Lib\site-packages\django\core\handlers\exception.py", line 55, in inner
    response = get_response(request)
               ^^^^^^^^^^^^^^^^^^^^^
  File "C:\Users\dara3\AppData\Local\Programs\Python\Python311\Lib\site-packages\django\core\handlers\base.py", line 197, in _get_response
    response = wrapped_callback(request, *callback_args, **callback_kwargs)
               ^^^^^^^^^^^^^^^^^^^^^^^^^^^^^^^^^^^^^^^^^^^^^^^^^^^^^^^^^^^^
  File "D:\GB\HTML CSS\Django\hw1\hw1app\views.py", line 107, in del_good
    good = Goods.objects.filter(id=request).first()
           ^^^^^^^^^^^^^^^^^^^^^^^^^^^^^^^^
  File "C:\Users\dara3\AppData\Local\Programs\Python\Python311\Lib\site-packages\django\db\models\manager.py", line 87, in manager_method
    return getattr(self.get_queryset(), name)(*args, **kwargs)
           ^^^^^^^^^^^^^^^^^^^^^^^^^^^^^^^^^^^^^^^^^^^^^^^^^^^
  File "C:\Users\dara3\AppData\Local\Programs\Python\Python311\Lib\site-packages\django\db\models\query.py", line 1476, in filter
    return self._filter_or_exclude(False, args, kwargs)
           ^^^^^^^^^^^^^^^^^^^^^^^^^^^^^^^^^^^^^^^^^^^^
  File "C:\Users\dara3\AppData\Local\Programs\Python\Python311\Lib\site-packages\django\db\models\query.py", line 1494, in _filter_or_exclude
    clone._filter_or_exclude_inplace(negate, args, kwargs)
  File "C:\Users\dara3\AppData\Local\Programs\Python\Python311\Lib\site-packages\django\db\models\query.py", line 1501, in _filter_or_exclude_inplace
    self._query.add_q(Q(*args, **kwargs))
  File "C:\Users\dara3\AppData\Local\Programs\Python\Python311\Lib\site-packages\django\db\models\sql\query.py", line 1613, in add_q
    clause, _ = self._add_q(q_object, self.used_aliases)
                ^^^^^^^^^^^^^^^^^^^^^^^^^^^^^^^^^^^^^^^^
  File "C:\Users\dara3\AppData\Local\Programs\Python\Python311\Lib\site-packages\django\db\models\sql\query.py", line 1645, in _add_q
    child_clause, needed_inner = self.build_filter(
                                 ^^^^^^^^^^^^^^^^^^
  File "C:\Users\dara3\AppData\Local\Programs\Python\Python311\Lib\site-packages\django\db\models\sql\query.py", line 1559, in build_filter
    condition = self.build_lookup(lookups, col, value)
                ^^^^^^^^^^^^^^^^^^^^^^^^^^^^^^^^^^^^^^
  File "C:\Users\dara3\AppData\Local\Programs\Python\Python311\Lib\site-packages\django\db\models\sql\query.py", line 1389, in build_lookup
    lookup = lookup_class(lhs, rhs)
             ^^^^^^^^^^^^^^^^^^^^^^
  File "C:\Users\dara3\AppData\Local\Programs\Python\Python311\Lib\site-packages\django\db\models\lookups.py", line 30, in __init__
    self.rhs = self.get_prep_lookup()
               ^^^^^^^^^^^^^^^^^^^^^^
  File "C:\Users\dara3\AppData\Local\Programs\Python\Python311\Lib\site-packages\django\db\models\lookups.py", line 364, in get_prep_lookup
    return super().get_prep_lookup()
           ^^^^^^^^^^^^^^^^^^^^^^^^^
  File "C:\Users\dara3\AppData\Local\Programs\Python\Python311\Lib\site-packages\django\db\models\lookups.py", line 88, in get_prep_lookup
    return self.lhs.output_field.get_prep_value(self.rhs)
           ^^^^^^^^^^^^^^^^^^^^^^^^^^^^^^^^^^^^^^^^^^^^^^
  File "C:\Users\dara3\AppData\Local\Programs\Python\Python311\Lib\site-packages\django\db\models\fields\__init__.py", line 2119, in get_prep_value
    raise e.__class__(
TypeError: Field 'id' expected a number but got <WSGIRequest: GET '/del_good/'>.
"GET /del_good/ HTTP/1.1" 500 127351
D:\GB\HTML CSS\Django\hw1\hw1app\views.py changed, reloading.
Watching for file changes with StatReloader
D:\GB\HTML CSS\Django\hw1\hw1app\forms.py changed, reloading.
Watching for file changes with StatReloader
D:\GB\HTML CSS\Django\hw1\hw1\settings.py changed, reloading.
Watching for file changes with StatReloader
D:\GB\HTML CSS\Django\hw1\hw1app\views.py changed, reloading.
Watching for file changes with StatReloader
D:\GB\HTML CSS\Django\hw1\hw1app\views.py changed, reloading.
Watching for file changes with StatReloader
D:\GB\HTML CSS\Django\hw1\hw1app\views.py changed, reloading.
Watching for file changes with StatReloader
D:\GB\HTML CSS\Django\hw1\hw1app\views.py changed, reloading.
Watching for file changes with StatReloader
D:\GB\HTML CSS\Django\hw1\hw1app\views.py changed, reloading.
Watching for file changes with StatReloader
D:\GB\HTML CSS\Django\hw1\hw1app\urls.py changed, reloading.
Watching for file changes with StatReloader
Internal Server Error: /upload/
Traceback (most recent call last):
  File "C:\Users\dara3\AppData\Local\Programs\Python\Python311\Lib\site-packages\django\template\backends\django.py", line 61, in render
    return self.template.render(context)
           ^^^^^^^^^^^^^^^^^^^^^^^^^^^^^
  File "C:\Users\dara3\AppData\Local\Programs\Python\Python311\Lib\site-packages\django\template\base.py", line 171, in render
    return self._render(context)
           ^^^^^^^^^^^^^^^^^^^^^
  File "C:\Users\dara3\AppData\Local\Programs\Python\Python311\Lib\site-packages\django\template\base.py", line 163, in _render
    return self.nodelist.render(context)
           ^^^^^^^^^^^^^^^^^^^^^^^^^^^^^
  File "C:\Users\dara3\AppData\Local\Programs\Python\Python311\Lib\site-packages\django\template\base.py", line 1000, in render
    return SafeString("".join([node.render_annotated(context) for node in self]))
                              ^^^^^^^^^^^^^^^^^^^^^^^^^^^^^^^^^^^^^^^^^^^^^^^^^
  File "C:\Users\dara3\AppData\Local\Programs\Python\Python311\Lib\site-packages\django\template\base.py", line 1000, in <listcomp>
    return SafeString("".join([node.render_annotated(context) for node in self]))
                               ^^^^^^^^^^^^^^^^^^^^^^^^^^^^^^
  File "C:\Users\dara3\AppData\Local\Programs\Python\Python311\Lib\site-packages\django\template\base.py", line 961, in render_annotated
    return self.render(context)
           ^^^^^^^^^^^^^^^^^^^^
  File "C:\Users\dara3\AppData\Local\Programs\Python\Python311\Lib\site-packages\django\template\loader_tags.py", line 134, in render
    compiled_parent = self.get_parent(context)
                      ^^^^^^^^^^^^^^^^^^^^^^^^
  File "C:\Users\dara3\AppData\Local\Programs\Python\Python311\Lib\site-packages\django\template\loader_tags.py", line 131, in get_parent
    return self.find_template(parent, context)
           ^^^^^^^^^^^^^^^^^^^^^^^^^^^^^^^^^^^
  File "C:\Users\dara3\AppData\Local\Programs\Python\Python311\Lib\site-packages\django\template\loader_tags.py", line 109, in find_template
    template, origin = context.template.engine.find_template(
                       ^^^^^^^^^^^^^^^^^^^^^^^^^^^^^^^^^^^^^^
  File "C:\Users\dara3\AppData\Local\Programs\Python\Python311\Lib\site-packages\django\template\engine.py", line 163, in find_template
    raise TemplateDoesNotExist(name, tried=tried)
django.template.exceptions.TemplateDoesNotExist: base.html

The above exception was the direct cause of the following exception:

Traceback (most recent call last):
  File "C:\Users\dara3\AppData\Local\Programs\Python\Python311\Lib\site-packages\django\core\handlers\exception.py", line 55, in inner
    response = get_response(request)
               ^^^^^^^^^^^^^^^^^^^^^
  File "C:\Users\dara3\AppData\Local\Programs\Python\Python311\Lib\site-packages\django\core\handlers\base.py", line 197, in _get_response
    response = wrapped_callback(request, *callback_args, **callback_kwargs)
               ^^^^^^^^^^^^^^^^^^^^^^^^^^^^^^^^^^^^^^^^^^^^^^^^^^^^^^^^^^^^
  File "D:\GB\HTML CSS\Django\hw1\hw1app\views.py", line 135, in upload_image
    return render(request, 'hw1app/upload_image.html', {'form':form})
           ^^^^^^^^^^^^^^^^^^^^^^^^^^^^^^^^^^^^^^^^^^^^^^^^^^^^^^^^^^
  File "C:\Users\dara3\AppData\Local\Programs\Python\Python311\Lib\site-packages\django\shortcuts.py", line 25, in render
    content = loader.render_to_string(template_name, context, request, using=using)
              ^^^^^^^^^^^^^^^^^^^^^^^^^^^^^^^^^^^^^^^^^^^^^^^^^^^^^^^^^^^^^^^^^^^^^
  File "C:\Users\dara3\AppData\Local\Programs\Python\Python311\Lib\site-packages\django\template\loader.py", line 62, in render_to_string
    return template.render(context, request)
           ^^^^^^^^^^^^^^^^^^^^^^^^^^^^^^^^^
  File "C:\Users\dara3\AppData\Local\Programs\Python\Python311\Lib\site-packages\django\template\backends\django.py", line 63, in render
    reraise(exc, self.backend)
  File "C:\Users\dara3\AppData\Local\Programs\Python\Python311\Lib\site-packages\django\template\backends\django.py", line 84, in reraise
    raise new from exc
django.template.exceptions.TemplateDoesNotExist: base.html
"GET /upload/ HTTP/1.1" 500 128680
"GET /upload/ HTTP/1.1" 200 599
Internal Server Error: /upload/
Traceback (most recent call last):
  File "C:\Users\dara3\AppData\Local\Programs\Python\Python311\Lib\site-packages\django\core\handlers\exception.py", line 55, in inner
    response = get_response(request)
               ^^^^^^^^^^^^^^^^^^^^^
  File "C:\Users\dara3\AppData\Local\Programs\Python\Python311\Lib\site-packages\django\core\handlers\base.py", line 197, in _get_response
    response = wrapped_callback(request, *callback_args, **callback_kwargs)
               ^^^^^^^^^^^^^^^^^^^^^^^^^^^^^^^^^^^^^^^^^^^^^^^^^^^^^^^^^^^^
  File "D:\GB\HTML CSS\Django\hw1\hw1app\views.py", line 129, in upload_image
    if form.is_valid():
       ^^^^^^^^^^^^^^^
  File "C:\Users\dara3\AppData\Local\Programs\Python\Python311\Lib\site-packages\django\forms\forms.py", line 197, in is_valid
    return self.is_bound and not self.errors
                                 ^^^^^^^^^^^
  File "C:\Users\dara3\AppData\Local\Programs\Python\Python311\Lib\site-packages\django\forms\forms.py", line 192, in errors
    self.full_clean()
  File "C:\Users\dara3\AppData\Local\Programs\Python\Python311\Lib\site-packages\django\forms\forms.py", line 327, in full_clean
    self._clean_fields()
  File "C:\Users\dara3\AppData\Local\Programs\Python\Python311\Lib\site-packages\django\forms\forms.py", line 337, in _clean_fields
    value = field.clean(value, bf.initial)
            ^^^^^^^^^^^^^^^^^^^^^^^^^^^^^^
  File "C:\Users\dara3\AppData\Local\Programs\Python\Python311\Lib\site-packages\django\forms\fields.py", line 689, in clean
    return super().clean(data)
           ^^^^^^^^^^^^^^^^^^^
  File "C:\Users\dara3\AppData\Local\Programs\Python\Python311\Lib\site-packages\django\forms\fields.py", line 204, in clean
    value = self.to_python(value)
            ^^^^^^^^^^^^^^^^^^^^^
  File "C:\Users\dara3\AppData\Local\Programs\Python\Python311\Lib\site-packages\django\forms\fields.py", line 716, in to_python
    from PIL import Image
ModuleNotFoundError: No module named 'PIL'
"POST /upload/ HTTP/1.1" 500 93553
D:\GB\HTML CSS\Django\hw1\hw1app\views.py changed, reloading.
Watching for file changes with StatReloader
Watching for file changes with StatReloader
Watching for file changes with StatReloader
"GET /upload/ HTTP/1.1" 200 599
"POST /upload/ HTTP/1.1" 200 599
"POST /upload/ HTTP/1.1" 200 747
D:\GB\HTML CSS\Django\hw1\hw1app\views.py changed, reloading.
Watching for file changes with StatReloader
D:\GB\HTML CSS\Django\hw1\hw1app\views.py changed, reloading.
Watching for file changes with StatReloader
D:\GB\HTML CSS\Django\hw1\hw1app\views.py changed, reloading.
Watching for file changes with StatReloader
D:\GB\HTML CSS\Django\hw1\hw1app\views.py changed, reloading.
Watching for file changes with StatReloader
D:\GB\HTML CSS\Django\hw1\hw1app\views.py changed, reloading.
Watching for file changes with StatReloader
D:\GB\HTML CSS\Django\hw1\hw1app\views.py changed, reloading.
Watching for file changes with StatReloader
"GET /del_good/ HTTP/1.1" 200 521
Internal Server Error: /del_good/
Traceback (most recent call last):
  File "D:\GB\HTML CSS\Django\venv\Lib\site-packages\django\core\handlers\exception.py", line 55, in inner
    response = get_response(request)
               ^^^^^^^^^^^^^^^^^^^^^
  File "D:\GB\HTML CSS\Django\venv\Lib\site-packages\django\core\handlers\base.py", line 197, in _get_response
    response = wrapped_callback(request, *callback_args, **callback_kwargs)
               ^^^^^^^^^^^^^^^^^^^^^^^^^^^^^^^^^^^^^^^^^^^^^^^^^^^^^^^^^^^^
  File "D:\GB\HTML CSS\Django\hw1\hw1app\views.py", line 114, in del_good
    doog.delete()
    ^^^^^^^^^^^
AttributeError: 'NoneType' object has no attribute 'delete'
"POST /del_good/ HTTP/1.1" 500 66465
D:\GB\HTML CSS\Django\hw1\hw1app\views.py changed, reloading.
Watching for file changes with StatReloader
Watching for file changes with StatReloader
"GET /del_good/ HTTP/1.1" 200 501
Internal Server Error: /del_good/
Traceback (most recent call last):
  File "D:\GB\HTML CSS\Django\venv\Lib\site-packages\django\core\handlers\exception.py", line 55, in inner
    response = get_response(request)
               ^^^^^^^^^^^^^^^^^^^^^
  File "D:\GB\HTML CSS\Django\venv\Lib\site-packages\django\core\handlers\base.py", line 197, in _get_response
    response = wrapped_callback(request, *callback_args, **callback_kwargs)
               ^^^^^^^^^^^^^^^^^^^^^^^^^^^^^^^^^^^^^^^^^^^^^^^^^^^^^^^^^^^^
  File "D:\GB\HTML CSS\Django\hw1\hw1app\views.py", line 115, in del_good
    doog.delete()
    ^^^^^^^^^^^
AttributeError: 'NoneType' object has no attribute 'delete'
"POST /del_good/ HTTP/1.1" 500 66647
D:\GB\HTML CSS\Django\hw1\hw1app\views.py changed, reloading.
Watching for file changes with StatReloader
"GET /del_good/ HTTP/1.1" 200 501
Internal Server Error: /del_good/
Traceback (most recent call last):
  File "D:\GB\HTML CSS\Django\venv\Lib\site-packages\django\core\handlers\exception.py", line 55, in inner
    response = get_response(request)
               ^^^^^^^^^^^^^^^^^^^^^
  File "D:\GB\HTML CSS\Django\venv\Lib\site-packages\django\core\handlers\base.py", line 197, in _get_response
    response = wrapped_callback(request, *callback_args, **callback_kwargs)
               ^^^^^^^^^^^^^^^^^^^^^^^^^^^^^^^^^^^^^^^^^^^^^^^^^^^^^^^^^^^^
  File "D:\GB\HTML CSS\Django\hw1\hw1app\views.py", line 115, in del_good
    id.delete()
    ^^^^^^^^^
AttributeError: 'int' object has no attribute 'delete'
"POST /del_good/ HTTP/1.1" 500 66461
D:\GB\HTML CSS\Django\hw1\hw1app\forms.py changed, reloading.
Watching for file changes with StatReloader
"GET /del_good/ HTTP/1.1" 200 499
Internal Server Error: /del_good/
Traceback (most recent call last):
  File "D:\GB\HTML CSS\Django\venv\Lib\site-packages\django\core\handlers\exception.py", line 55, in inner
    response = get_response(request)
               ^^^^^^^^^^^^^^^^^^^^^
  File "D:\GB\HTML CSS\Django\venv\Lib\site-packages\django\core\handlers\base.py", line 197, in _get_response
    response = wrapped_callback(request, *callback_args, **callback_kwargs)
               ^^^^^^^^^^^^^^^^^^^^^^^^^^^^^^^^^^^^^^^^^^^^^^^^^^^^^^^^^^^^
  File "D:\GB\HTML CSS\Django\hw1\hw1app\views.py", line 115, in del_good
    id.delete()
    ^^^^^^^^^
AttributeError: 'str' object has no attribute 'delete'
"POST /del_good/ HTTP/1.1" 500 66473
D:\GB\HTML CSS\Django\hw1\hw1app\views.py changed, reloading.
Watching for file changes with StatReloader
"GET /del_good/ HTTP/1.1" 200 499
Internal Server Error: /del_good/
Traceback (most recent call last):
  File "D:\GB\HTML CSS\Django\venv\Lib\site-packages\django\core\handlers\exception.py", line 55, in inner
    response = get_response(request)
               ^^^^^^^^^^^^^^^^^^^^^
  File "D:\GB\HTML CSS\Django\venv\Lib\site-packages\django\core\handlers\base.py", line 197, in _get_response
    response = wrapped_callback(request, *callback_args, **callback_kwargs)
               ^^^^^^^^^^^^^^^^^^^^^^^^^^^^^^^^^^^^^^^^^^^^^^^^^^^^^^^^^^^^
  File "D:\GB\HTML CSS\Django\hw1\hw1app\views.py", line 114, in del_good
    pk = form.cleaned_data['id']
         ~~~~~~~~~~~~~~~~~^^^^^^
KeyError: 'id'
"POST /del_good/ HTTP/1.1" 500 66279
D:\GB\HTML CSS\Django\hw1\hw1app\views.py changed, reloading.
Watching for file changes with StatReloader
"GET /del_good/ HTTP/1.1" 200 499
Internal Server Error: /del_good/
Traceback (most recent call last):
  File "D:\GB\HTML CSS\Django\venv\Lib\site-packages\django\core\handlers\exception.py", line 55, in inner
    response = get_response(request)
               ^^^^^^^^^^^^^^^^^^^^^
  File "D:\GB\HTML CSS\Django\venv\Lib\site-packages\django\core\handlers\base.py", line 197, in _get_response
    response = wrapped_callback(request, *callback_args, **callback_kwargs)
               ^^^^^^^^^^^^^^^^^^^^^^^^^^^^^^^^^^^^^^^^^^^^^^^^^^^^^^^^^^^^
  File "D:\GB\HTML CSS\Django\hw1\hw1app\views.py", line 115, in del_good
    pk.delete()
    ^^^^^^^^^
AttributeError: 'str' object has no attribute 'delete'
"POST /del_good/ HTTP/1.1" 500 66473
D:\GB\HTML CSS\Django\hw1\hw1app\forms.py changed, reloading.
Watching for file changes with StatReloader
D:\GB\HTML CSS\Django\hw1\hw1app\models.py changed, reloading.
Watching for file changes with StatReloader
D:\GB\HTML CSS\Django\hw1\hw1app\models.py changed, reloading.
Watching for file changes with StatReloader
Watching for file changes with StatReloader
"GET /upload/ HTTP/1.1" 200 1195
Internal Server Error: /upload/
Traceback (most recent call last):
  File "D:\GB\HTML CSS\Django\venv\Lib\site-packages\django\core\handlers\exception.py", line 55, in inner
    response = get_response(request)
               ^^^^^^^^^^^^^^^^^^^^^
  File "D:\GB\HTML CSS\Django\venv\Lib\site-packages\django\core\handlers\base.py", line 197, in _get_response
    response = wrapped_callback(request, *callback_args, **callback_kwargs)
               ^^^^^^^^^^^^^^^^^^^^^^^^^^^^^^^^^^^^^^^^^^^^^^^^^^^^^^^^^^^^
  File "D:\GB\HTML CSS\Django\hw1\hw1app\views.py", line 127, in upload_image
    fs.save(image.name, image)
  File "D:\GB\HTML CSS\Django\venv\Lib\site-packages\django\db\models\base.py", line 782, in save
    raise ValueError("Cannot force both insert and updating in model saving.")
ValueError: Cannot force both insert and updating in model saving.
"POST /upload/ HTTP/1.1" 500 71603
D:\GB\HTML CSS\Django\hw1\hw1app\views.py changed, reloading.
Watching for file changes with StatReloader
"GET /add_goods HTTP/1.1" 301 0
"GET /add_goods/ HTTP/1.1" 200 1155
Internal Server Error: /add_goods/
Traceback (most recent call last):
  File "D:\GB\HTML CSS\Django\venv\Lib\site-packages\django\core\handlers\exception.py", line 55, in inner
    response = get_response(request)
               ^^^^^^^^^^^^^^^^^^^^^
  File "D:\GB\HTML CSS\Django\venv\Lib\site-packages\django\core\handlers\base.py", line 197, in _get_response
    response = wrapped_callback(request, *callback_args, **callback_kwargs)
               ^^^^^^^^^^^^^^^^^^^^^^^^^^^^^^^^^^^^^^^^^^^^^^^^^^^^^^^^^^^^
  File "D:\GB\HTML CSS\Django\hw1\hw1app\views.py", line 91, in add_goods
    return render(request, 'hw1app/add_goods.html', {'form': form, 'message': message})
                                                                              ^^^^^^^
UnboundLocalError: cannot access local variable 'message' where it is not associated with a value
"POST /add_goods/ HTTP/1.1" 500 67265
D:\GB\HTML CSS\Django\hw1\hw1app\views.py changed, reloading.
Watching for file changes with StatReloader
"GET /add_goods/ HTTP/1.1" 200 1128
"POST /add_goods/ HTTP/1.1" 200 1251
"POST /add_goods/ HTTP/1.1" 200 1251
"GET /add_goods/ HTTP/1.1" 200 1128
D:\GB\HTML CSS\Django\hw1\hw1app\views.py changed, reloading.
Watching for file changes with StatReloader
"GET /add_goods/ HTTP/1.1" 200 1128
D:\GB\HTML CSS\Django\hw1\hw1app\models.py changed, reloading.
Watching for file changes with StatReloader
"GET /add_goods/ HTTP/1.1" 200 1128
"GET /add_goods/ HTTP/1.1" 200 1128
D:\GB\HTML CSS\Django\hw1\hw1app\forms.py changed, reloading.
Watching for file changes with StatReloader
"GET /add_goods/ HTTP/1.1" 200 983
"GET /add_goods/ HTTP/1.1" 200 983
Internal Server Error: /add_goods/
Traceback (most recent call last):
  File "D:\GB\HTML CSS\Django\venv\Lib\site-packages\django\core\handlers\exception.py", line 55, in inner
    response = get_response(request)
               ^^^^^^^^^^^^^^^^^^^^^
  File "D:\GB\HTML CSS\Django\venv\Lib\site-packages\django\core\handlers\base.py", line 197, in _get_response
    response = wrapped_callback(request, *callback_args, **callback_kwargs)
               ^^^^^^^^^^^^^^^^^^^^^^^^^^^^^^^^^^^^^^^^^^^^^^^^^^^^^^^^^^^^
  File "D:\GB\HTML CSS\Django\hw1\hw1app\views.py", line 81, in add_goods
    date_of_add = form.cleaned_data['date_of_add']
                  ~~~~~~~~~~~~~~~~~^^^^^^^^^^^^^^^
KeyError: 'date_of_add'
"POST /add_goods/ HTTP/1.1" 500 67530
D:\GB\HTML CSS\Django\hw1\hw1app\views.py changed, reloading.
Watching for file changes with StatReloader
"GET /add_goods/ HTTP/1.1" 200 1320
"POST /add_goods/ HTTP/1.1" 200 1439
"POST /add_goods/ HTTP/1.1" 200 1439
D:\GB\HTML CSS\Django\hw1\hw1app\views.py changed, reloading.
Watching for file changes with StatReloader
"GET /add_goods/ HTTP/1.1" 200 1320
"POST /add_goods/ HTTP/1.1" 200 1439
D:\GB\HTML CSS\Django\hw1\hw1app\views.py changed, reloading.
Watching for file changes with StatReloader
D:\GB\HTML CSS\Django\hw1\hw1app\views.py changed, reloading.
Watching for file changes with StatReloader
D:\GB\HTML CSS\Django\hw1\hw1app\views.py changed, reloading.
Watching for file changes with StatReloader
"GET /add_goods/ HTTP/1.1" 200 1320
"POST /add_goods/ HTTP/1.1" 200 1439
D:\GB\HTML CSS\Django\hw1\hw1app\views.py changed, reloading.
Watching for file changes with StatReloader
"GET /add_goods/ HTTP/1.1" 200 1320
"POST /add_goods/ HTTP/1.1" 200 1439
"POST /add_goods/ HTTP/1.1" 200 1439
D:\GB\HTML CSS\Django\hw1\hw1app\models.py changed, reloading.
Watching for file changes with StatReloader
"GET /add_goods/ HTTP/1.1" 200 1320
"POST /add_goods/ HTTP/1.1" 200 1439
D:\GB\HTML CSS\Django\hw1\hw1app\views.py changed, reloading.
Watching for file changes with StatReloader
"GET /add_goods/ HTTP/1.1" 200 1320
"POST /add_goods/ HTTP/1.1" 200 1439
D:\GB\HTML CSS\Django\hw1\hw1app\views.py changed, reloading.
Watching for file changes with StatReloader
D:\GB\HTML CSS\Django\hw1\hw1app\models.py changed, reloading.
Watching for file changes with StatReloader
Watching for file changes with StatReloader
Watching for file changes with StatReloader
"POST /add_goods/ HTTP/1.1" 200 1439
"GET /add_goods/ HTTP/1.1" 200 1320
"POST /add_goods/ HTTP/1.1" 200 1439
D:\GB\HTML CSS\Django\hw1\hw1app\models.py changed, reloading.
Watching for file changes with StatReloader
Watching for file changes with StatReloader
"GET /add_goods/ HTTP/1.1" 200 1320
"POST /add_goods/ HTTP/1.1" 200 1439
D:\GB\HTML CSS\Django\hw1\hw1app\forms.py changed, reloading.
Watching for file changes with StatReloader
"GET /add_goods/ HTTP/1.1" 200 1311
Internal Server Error: /add_goods/
Traceback (most recent call last):
  File "D:\GB\HTML CSS\Django\venv\Lib\site-packages\django\core\handlers\exception.py", line 55, in inner
    response = get_response(request)
               ^^^^^^^^^^^^^^^^^^^^^
  File "D:\GB\HTML CSS\Django\venv\Lib\site-packages\django\core\handlers\base.py", line 197, in _get_response
    response = wrapped_callback(request, *callback_args, **callback_kwargs)
               ^^^^^^^^^^^^^^^^^^^^^^^^^^^^^^^^^^^^^^^^^^^^^^^^^^^^^^^^^^^^
  File "D:\GB\HTML CSS\Django\hw1\hw1app\views.py", line 84, in add_goods
    fs.save(image.name, image)
            ^^^^^^^^^^
AttributeError: 'NoneType' object has no attribute 'name'
"POST /add_goods/ HTTP/1.1" 500 68512
"GET /add_goods/ HTTP/1.1" 200 1311
Internal Server Error: /add_goods/
Traceback (most recent call last):
  File "D:\GB\HTML CSS\Django\venv\Lib\site-packages\django\core\handlers\exception.py", line 55, in inner
    response = get_response(request)
               ^^^^^^^^^^^^^^^^^^^^^
  File "D:\GB\HTML CSS\Django\venv\Lib\site-packages\django\core\handlers\base.py", line 197, in _get_response
    response = wrapped_callback(request, *callback_args, **callback_kwargs)
               ^^^^^^^^^^^^^^^^^^^^^^^^^^^^^^^^^^^^^^^^^^^^^^^^^^^^^^^^^^^^
  File "D:\GB\HTML CSS\Django\hw1\hw1app\views.py", line 84, in add_goods
    fs.save(image.name, image)
            ^^^^^^^^^^
AttributeError: 'NoneType' object has no attribute 'name'
"POST /add_goods/ HTTP/1.1" 500 68502
D:\GB\HTML CSS\Django\hw1\hw1app\views.py changed, reloading.
Watching for file changes with StatReloader
"GET /add_goods/ HTTP/1.1" 200 1311
Internal Server Error: /add_goods/
Traceback (most recent call last):
  File "D:\GB\HTML CSS\Django\venv\Lib\site-packages\django\core\handlers\exception.py", line 55, in inner
    response = get_response(request)
               ^^^^^^^^^^^^^^^^^^^^^
  File "D:\GB\HTML CSS\Django\venv\Lib\site-packages\django\core\handlers\base.py", line 197, in _get_response
    response = wrapped_callback(request, *callback_args, **callback_kwargs)
               ^^^^^^^^^^^^^^^^^^^^^^^^^^^^^^^^^^^^^^^^^^^^^^^^^^^^^^^^^^^^
  File "D:\GB\HTML CSS\Django\hw1\hw1app\views.py", line 144, in add_goods
    fs.save(image.name, image)
            ^^^^^^^^^^
AttributeError: 'NoneType' object has no attribute 'name'
"POST /add_goods/ HTTP/1.1" 500 68509
D:\GB\HTML CSS\Django\hw1\hw1app\views.py changed, reloading.
Watching for file changes with StatReloader
"GET /add_goods/ HTTP/1.1" 200 1311
"POST /add_goods/ HTTP/1.1" 200 1311
D:\GB\HTML CSS\Django\hw1\hw1app\views.py changed, reloading.
Watching for file changes with StatReloader
"GET /add_goods/ HTTP/1.1" 200 1338
"POST /add_goods/ HTTP/1.1" 200 1342
D:\GB\HTML CSS\Django\hw1\hw1app\views.py changed, reloading.
Watching for file changes with StatReloader
Not Found: /add_images/
"GET /add_images/ HTTP/1.1" 404 3560
"GET /upload/ HTTP/1.1" 200 1311
Internal Server Error: /upload/
Traceback (most recent call last):
  File "D:\GB\HTML CSS\Django\venv\Lib\site-packages\django\core\handlers\exception.py", line 55, in inner
    response = get_response(request)
               ^^^^^^^^^^^^^^^^^^^^^
  File "D:\GB\HTML CSS\Django\venv\Lib\site-packages\django\core\handlers\base.py", line 197, in _get_response
    response = wrapped_callback(request, *callback_args, **callback_kwargs)
               ^^^^^^^^^^^^^^^^^^^^^^^^^^^^^^^^^^^^^^^^^^^^^^^^^^^^^^^^^^^^
  File "D:\GB\HTML CSS\Django\hw1\hw1app\views.py", line 139, in add_images
    fs.save(image.name, image)
            ^^^^^^^^^^
AttributeError: 'NoneType' object has no attribute 'name'
"POST /upload/ HTTP/1.1" 500 67366
D:\GB\HTML CSS\Django\hw1\hw1app\urls.py changed, reloading.
Watching for file changes with StatReloader
"GET /upload/ HTTP/1.1" 200 599
"POST /upload/ HTTP/1.1" 200 599
D:\GB\HTML CSS\Django\hw1\hw1app\urls.py changed, reloading.
Watching for file changes with StatReloader
"GET /uploadi/ HTTP/1.1" 200 1311
Internal Server Error: /uploadi/
Traceback (most recent call last):
  File "D:\GB\HTML CSS\Django\venv\Lib\site-packages\django\core\handlers\exception.py", line 55, in inner
    response = get_response(request)
               ^^^^^^^^^^^^^^^^^^^^^
  File "D:\GB\HTML CSS\Django\venv\Lib\site-packages\django\core\handlers\base.py", line 197, in _get_response
    response = wrapped_callback(request, *callback_args, **callback_kwargs)
               ^^^^^^^^^^^^^^^^^^^^^^^^^^^^^^^^^^^^^^^^^^^^^^^^^^^^^^^^^^^^
  File "D:\GB\HTML CSS\Django\hw1\hw1app\views.py", line 139, in add_images
    fs.save(image.name, image)
            ^^^^^^^^^^
AttributeError: 'NoneType' object has no attribute 'name'
"POST /uploadi/ HTTP/1.1" 500 67372
D:\GB\HTML CSS\Django\hw1\hw1app\forms.py changed, reloading.
Watching for file changes with StatReloader
"GET /uploadi/ HTTP/1.1" 200 1320
Internal Server Error: /uploadi/
Traceback (most recent call last):
  File "D:\GB\HTML CSS\Django\venv\Lib\site-packages\django\core\handlers\exception.py", line 55, in inner
    response = get_response(request)
               ^^^^^^^^^^^^^^^^^^^^^
  File "D:\GB\HTML CSS\Django\venv\Lib\site-packages\django\core\handlers\base.py", line 197, in _get_response
    response = wrapped_callback(request, *callback_args, **callback_kwargs)
               ^^^^^^^^^^^^^^^^^^^^^^^^^^^^^^^^^^^^^^^^^^^^^^^^^^^^^^^^^^^^
  File "D:\GB\HTML CSS\Django\hw1\hw1app\views.py", line 139, in add_images
    fs.save(image.name, image)
            ^^^^^
UnboundLocalError: cannot access local variable 'image' where it is not associated with a value
"POST /uploadi/ HTTP/1.1" 500 67326
Watching for file changes with StatReloader
"GET / HTTP/1.1" 200 90
Not Found: /favicon.ico
"GET /favicon.ico HTTP/1.1" 404 3736
"GET /admin HTTP/1.1" 301 0
"GET /admin/ HTTP/1.1" 302 0
"GET /admin/login/?next=/admin/ HTTP/1.1" 200 4158
"GET /static/admin/css/base.css HTTP/1.1" 200 21544
"GET /static/admin/js/nav_sidebar.js HTTP/1.1" 200 3063
"GET /static/admin/css/responsive.css HTTP/1.1" 200 17905
"GET /static/admin/css/dark_mode.css HTTP/1.1" 200 2682
"GET /static/admin/css/login.css HTTP/1.1" 200 958
"GET /static/admin/css/nav_sidebar.css HTTP/1.1" 200 2810
"GET /static/admin/js/theme.js HTTP/1.1" 200 1943
Watching for file changes with StatReloader
"GET /admin/ HTTP/1.1" 302 0
"GET /admin/login/?next=/admin/ HTTP/1.1" 200 4158
"POST /admin/login/?next=/admin/ HTTP/1.1" 302 0
"GET /admin/ HTTP/1.1" 200 5538
"GET /static/admin/css/dashboard.css HTTP/1.1" 200 441
"GET /static/admin/img/icon-changelink.svg HTTP/1.1" 200 380
"GET /static/admin/img/icon-addlink.svg HTTP/1.1" 200 331
D:\GB\HTML CSS\Django\hw1\hw1\settings.py changed, reloading.
Watching for file changes with StatReloader
"GET /admin/ HTTP/1.1" 200 5949
D:\GB\HTML CSS\Django\hw1\hw1app\admin.py changed, reloading.
Watching for file changes with StatReloader
"GET /admin/ HTTP/1.1" 200 7507
"GET /admin/hw1app/client/add/ HTTP/1.1" 200 12098
"GET /admin/jsi18n/ HTTP/1.1" 200 17546
"GET /static/admin/css/forms.css HTTP/1.1" 200 9090
"GET /static/admin/js/admin/RelatedObjectLookups.js HTTP/1.1" 200 9042
"GET /static/admin/css/widgets.css HTTP/1.1" 200 11800
"GET /static/admin/js/actions.js HTTP/1.1" 200 8067
"GET /static/admin/js/calendar.js HTTP/1.1" 200 9141
"GET /static/admin/js/jquery.init.js HTTP/1.1" 200 347
"GET /static/admin/js/urlify.js HTTP/1.1" 200 7887
"GET /static/admin/js/admin/DateTimeShortcuts.js HTTP/1.1" 200 19319
"GET /static/admin/js/core.js HTTP/1.1" 200 6208
"GET /static/admin/js/prepopulate_init.js HTTP/1.1" 200 586
"GET /static/admin/js/prepopulate.js HTTP/1.1" 200 1531
"GET /static/admin/js/vendor/jquery/jquery.js HTTP/1.1" 200 285314
"GET /static/admin/js/change_form.js HTTP/1.1" 200 606
"GET /static/admin/js/vendor/xregexp/xregexp.js HTTP/1.1" 200 325171
"GET /static/admin/img/icon-calendar.svg HTTP/1.1" 200 1086
"GET /static/admin/img/calendar-icons.svg HTTP/1.1" 200 1094
Invalid HTTP_HOST header: 'download.jetbrains.com'. You may need to add 'download.jetbrains.com' to ALLOWED_HOSTS.
Traceback (most recent call last):
  File "D:\GB\HTML CSS\Django\venv\Lib\site-packages\django\core\handlers\exception.py", line 55, in inner
    response = get_response(request)
               ^^^^^^^^^^^^^^^^^^^^^
  File "D:\GB\HTML CSS\Django\venv\Lib\site-packages\django\utils\deprecation.py", line 133, in __call__
    response = self.process_request(request)
               ^^^^^^^^^^^^^^^^^^^^^^^^^^^^^
  File "D:\GB\HTML CSS\Django\venv\Lib\site-packages\django\middleware\common.py", line 48, in process_request
    host = request.get_host()
           ^^^^^^^^^^^^^^^^^^
  File "D:\GB\HTML CSS\Django\venv\Lib\site-packages\django\http\request.py", line 151, in get_host
    raise DisallowedHost(msg)
django.core.exceptions.DisallowedHost: Invalid HTTP_HOST header: 'download.jetbrains.com'. You may need to add 'download.jetbrains.com' to ALLOWED_HOSTS.
Bad Request: /download.jetbrains.com:443
"CONNECT download.jetbrains.com:443 HTTP/1.1" 400 67350
"POST /admin/hw1app/client/add/ HTTP/1.1" 302 0
"GET /admin/hw1app/client/add/ HTTP/1.1" 200 12438
"GET /admin/jsi18n/ HTTP/1.1" 200 17546
"GET /static/admin/img/icon-yes.svg HTTP/1.1" 200 436
"GET /admin/hw1app/goods/ HTTP/1.1" 200 12481
"GET /static/admin/css/changelists.css HTTP/1.1" 200 6811
"GET /admin/jsi18n/ HTTP/1.1" 200 17546
"GET /static/admin/js/filters.js HTTP/1.1" 200 978
"GET /static/admin/img/tooltag-add.svg HTTP/1.1" 200 331
"GET /admin/hw1app/goods/10/change/ HTTP/1.1" 200 12969
"GET /admin/jsi18n/ HTTP/1.1" 200 17546
"GET /admin/hw1app/order/ HTTP/1.1" 200 8538
"GET /admin/jsi18n/ HTTP/1.1" 200 17546
"GET /admin/hw1app/client/ HTTP/1.1" 200 10174
"GET /admin/jsi18n/ HTTP/1.1" 200 17546
"GET /admin/hw1app/order/ HTTP/1.1" 200 8538
"GET /admin/jsi18n/ HTTP/1.1" 200 17546
"GET /admin/hw1app/order/add/ HTTP/1.1" 200 13005
"GET /admin/jsi18n/ HTTP/1.1" 200 17546
"GET /static/admin/img/icon-viewlink.svg HTTP/1.1" 200 581
"POST /admin/hw1app/order/add/ HTTP/1.1" 302 0
"GET /admin/hw1app/order/1/change/ HTTP/1.1" 200 13571
"GET /admin/jsi18n/ HTTP/1.1" 200 17546
"GET /admin/hw1app/order/ HTTP/1.1" 200 10066
"GET /admin/jsi18n/ HTTP/1.1" 200 17546
Invalid HTTP_HOST header: 'download.jetbrains.com'. You may need to add 'download.jetbrains.com' to ALLOWED_HOSTS.
Traceback (most recent call last):
  File "D:\GB\HTML CSS\Django\venv\Lib\site-packages\django\core\handlers\exception.py", line 55, in inner
    response = get_response(request)
               ^^^^^^^^^^^^^^^^^^^^^
  File "D:\GB\HTML CSS\Django\venv\Lib\site-packages\django\utils\deprecation.py", line 133, in __call__
    response = self.process_request(request)
               ^^^^^^^^^^^^^^^^^^^^^^^^^^^^^
  File "D:\GB\HTML CSS\Django\venv\Lib\site-packages\django\middleware\common.py", line 48, in process_request
    host = request.get_host()
           ^^^^^^^^^^^^^^^^^^
  File "D:\GB\HTML CSS\Django\venv\Lib\site-packages\django\http\request.py", line 151, in get_host
    raise DisallowedHost(msg)
django.core.exceptions.DisallowedHost: Invalid HTTP_HOST header: 'download.jetbrains.com'. You may need to add 'download.jetbrains.com' to ALLOWED_HOSTS.
Bad Request: /download.jetbrains.com:443
"CONNECT download.jetbrains.com:443 HTTP/1.1" 400 67350
"GET /admin/hw1app/goods/ HTTP/1.1" 200 12481
"GET /admin/jsi18n/ HTTP/1.1" 200 17546
Invalid HTTP_HOST header: 'download.jetbrains.com'. You may need to add 'download.jetbrains.com' to ALLOWED_HOSTS.
Traceback (most recent call last):
  File "D:\GB\HTML CSS\Django\venv\Lib\site-packages\django\core\handlers\exception.py", line 55, in inner
    response = get_response(request)
               ^^^^^^^^^^^^^^^^^^^^^
  File "D:\GB\HTML CSS\Django\venv\Lib\site-packages\django\utils\deprecation.py", line 133, in __call__
    response = self.process_request(request)
               ^^^^^^^^^^^^^^^^^^^^^^^^^^^^^
  File "D:\GB\HTML CSS\Django\venv\Lib\site-packages\django\middleware\common.py", line 48, in process_request
    host = request.get_host()
           ^^^^^^^^^^^^^^^^^^
  File "D:\GB\HTML CSS\Django\venv\Lib\site-packages\django\http\request.py", line 151, in get_host
    raise DisallowedHost(msg)
django.core.exceptions.DisallowedHost: Invalid HTTP_HOST header: 'download.jetbrains.com'. You may need to add 'download.jetbrains.com' to ALLOWED_HOSTS.
Bad Request: /download.jetbrains.com:443
"CONNECT download.jetbrains.com:443 HTTP/1.1" 400 67350
Invalid HTTP_HOST header: 'download.jetbrains.com'. You may need to add 'download.jetbrains.com' to ALLOWED_HOSTS.
Traceback (most recent call last):
  File "D:\GB\HTML CSS\Django\venv\Lib\site-packages\django\core\handlers\exception.py", line 55, in inner
    response = get_response(request)
               ^^^^^^^^^^^^^^^^^^^^^
  File "D:\GB\HTML CSS\Django\venv\Lib\site-packages\django\utils\deprecation.py", line 133, in __call__
    response = self.process_request(request)
               ^^^^^^^^^^^^^^^^^^^^^^^^^^^^^
  File "D:\GB\HTML CSS\Django\venv\Lib\site-packages\django\middleware\common.py", line 48, in process_request
    host = request.get_host()
           ^^^^^^^^^^^^^^^^^^
  File "D:\GB\HTML CSS\Django\venv\Lib\site-packages\django\http\request.py", line 151, in get_host
    raise DisallowedHost(msg)
django.core.exceptions.DisallowedHost: Invalid HTTP_HOST header: 'download.jetbrains.com'. You may need to add 'download.jetbrains.com' to ALLOWED_HOSTS.
Bad Request: /download.jetbrains.com:443
"CONNECT download.jetbrains.com:443 HTTP/1.1" 400 67350
"GET /admin/hw1app/goods/ HTTP/1.1" 200 12481
"GET /admin/jsi18n/ HTTP/1.1" 200 17546
"GET /admin/ HTTP/1.1" 200 8313
"GET /admin/auth/group/add/ HTTP/1.1" 200 14003
"GET /admin/jsi18n/ HTTP/1.1" 200 17546
"GET /static/admin/js/SelectBox.js HTTP/1.1" 200 4530
"GET /static/admin/js/SelectFilter2.js HTTP/1.1" 200 15492
"GET /static/admin/img/search.svg HTTP/1.1" 200 458
"GET /static/admin/img/selector-icons.svg HTTP/1.1" 200 3291
Invalid HTTP_HOST header: 'download.jetbrains.com'. You may need to add 'download.jetbrains.com' to ALLOWED_HOSTS.
Traceback (most recent call last):
  File "D:\GB\HTML CSS\Django\venv\Lib\site-packages\django\core\handlers\exception.py", line 55, in inner
    response = get_response(request)
               ^^^^^^^^^^^^^^^^^^^^^
  File "D:\GB\HTML CSS\Django\venv\Lib\site-packages\django\utils\deprecation.py", line 133, in __call__
    response = self.process_request(request)
               ^^^^^^^^^^^^^^^^^^^^^^^^^^^^^
  File "D:\GB\HTML CSS\Django\venv\Lib\site-packages\django\middleware\common.py", line 48, in process_request
    host = request.get_host()
           ^^^^^^^^^^^^^^^^^^
  File "D:\GB\HTML CSS\Django\venv\Lib\site-packages\django\http\request.py", line 151, in get_host
    raise DisallowedHost(msg)
django.core.exceptions.DisallowedHost: Invalid HTTP_HOST header: 'download.jetbrains.com'. You may need to add 'download.jetbrains.com' to ALLOWED_HOSTS.
Bad Request: /download.jetbrains.com:443
"CONNECT download.jetbrains.com:443 HTTP/1.1" 400 67350
"GET /static/admin/img/icon-unknown.svg HTTP/1.1" 200 655
"GET /static/admin/img/icon-unknown-alt.svg HTTP/1.1" 200 655
"POST /admin/auth/group/add/ HTTP/1.1" 302 0
"GET /admin/auth/group/add/ HTTP/1.1" 200 14300
"GET /admin/jsi18n/ HTTP/1.1" 200 17546
Invalid HTTP_HOST header: 'download.jetbrains.com'. You may need to add 'download.jetbrains.com' to ALLOWED_HOSTS.
Traceback (most recent call last):
  File "D:\GB\HTML CSS\Django\venv\Lib\site-packages\django\core\handlers\exception.py", line 55, in inner
    response = get_response(request)
               ^^^^^^^^^^^^^^^^^^^^^
  File "D:\GB\HTML CSS\Django\venv\Lib\site-packages\django\utils\deprecation.py", line 133, in __call__
    response = self.process_request(request)
               ^^^^^^^^^^^^^^^^^^^^^^^^^^^^^
  File "D:\GB\HTML CSS\Django\venv\Lib\site-packages\django\middleware\common.py", line 48, in process_request
    host = request.get_host()
           ^^^^^^^^^^^^^^^^^^
  File "D:\GB\HTML CSS\Django\venv\Lib\site-packages\django\http\request.py", line 151, in get_host
    raise DisallowedHost(msg)
django.core.exceptions.DisallowedHost: Invalid HTTP_HOST header: 'download.jetbrains.com'. You may need to add 'download.jetbrains.com' to ALLOWED_HOSTS.
Bad Request: /download.jetbrains.com:443
"CONNECT download.jetbrains.com:443 HTTP/1.1" 400 67350
"POST /admin/auth/group/add/ HTTP/1.1" 302 0
"GET /admin/auth/group/add/ HTTP/1.1" 200 14302
"GET /admin/jsi18n/ HTTP/1.1" 200 17546
"POST /admin/auth/group/add/ HTTP/1.1" 302 0
"GET /admin/auth/group/3/change/ HTTP/1.1" 200 14633
"GET /admin/jsi18n/ HTTP/1.1" 200 17546
"GET /admin/auth/group/ HTTP/1.1" 200 11142
"GET /admin/jsi18n/ HTTP/1.1" 200 17546
Invalid HTTP_HOST header: 'download.jetbrains.com'. You may need to add 'download.jetbrains.com' to ALLOWED_HOSTS.
Traceback (most recent call last):
  File "D:\GB\HTML CSS\Django\venv\Lib\site-packages\django\core\handlers\exception.py", line 55, in inner
    response = get_response(request)
               ^^^^^^^^^^^^^^^^^^^^^
  File "D:\GB\HTML CSS\Django\venv\Lib\site-packages\django\utils\deprecation.py", line 133, in __call__
    response = self.process_request(request)
               ^^^^^^^^^^^^^^^^^^^^^^^^^^^^^
  File "D:\GB\HTML CSS\Django\venv\Lib\site-packages\django\middleware\common.py", line 48, in process_request
    host = request.get_host()
           ^^^^^^^^^^^^^^^^^^
  File "D:\GB\HTML CSS\Django\venv\Lib\site-packages\django\http\request.py", line 151, in get_host
    raise DisallowedHost(msg)
django.core.exceptions.DisallowedHost: Invalid HTTP_HOST header: 'download.jetbrains.com'. You may need to add 'download.jetbrains.com' to ALLOWED_HOSTS.
Bad Request: /download.jetbrains.com:443
"CONNECT download.jetbrains.com:443 HTTP/1.1" 400 67350
"GET /admin/auth/user/add/ HTTP/1.1" 200 12383
"GET /admin/jsi18n/ HTTP/1.1" 200 17546
"POST /admin/auth/user/add/ HTTP/1.1" 302 0
"GET /admin/auth/user/add/ HTTP/1.1" 200 12692
"GET /admin/jsi18n/ HTTP/1.1" 200 17546
"POST /admin/auth/user/add/ HTTP/1.1" 302 0
"GET /admin/auth/user/add/ HTTP/1.1" 200 12692
"GET /admin/jsi18n/ HTTP/1.1" 200 17546
"POST /admin/auth/user/add/ HTTP/1.1" 302 0
"GET /admin/auth/user/add/ HTTP/1.1" 200 12692
"GET /admin/jsi18n/ HTTP/1.1" 200 17546
"GET /admin/auth/user/ HTTP/1.1" 200 15024
"GET /admin/jsi18n/ HTTP/1.1" 200 17546
"GET /static/admin/img/icon-no.svg HTTP/1.1" 200 560
"GET /static/admin/img/sorting-icons.svg HTTP/1.1" 200 1097
"GET /admin/auth/user/2/change/ HTTP/1.1" 200 24711
"GET /admin/jsi18n/ HTTP/1.1" 200 17546
"GET /static/admin/img/icon-clock.svg HTTP/1.1" 200 677
"POST /admin/auth/user/2/change/ HTTP/1.1" 302 0
"GET /admin/auth/user/2/change/ HTTP/1.1" 200 25018
"GET /admin/jsi18n/ HTTP/1.1" 200 17546
"GET /admin/auth/user/ HTTP/1.1" 200 15024
"GET /admin/jsi18n/ HTTP/1.1" 200 17546
"GET /admin/auth/user/3/change/ HTTP/1.1" 200 24711
"GET /admin/jsi18n/ HTTP/1.1" 200 17546
"POST /admin/auth/user/3/change/ HTTP/1.1" 302 0
"GET /admin/auth/user/add/ HTTP/1.1" 200 12675
"GET /admin/jsi18n/ HTTP/1.1" 200 17546
"GET /admin/auth/user/ HTTP/1.1" 200 15024
"GET /admin/jsi18n/ HTTP/1.1" 200 17546
"GET /admin/auth/user/4/change/ HTTP/1.1" 200 24711
"GET /admin/jsi18n/ HTTP/1.1" 200 17546
"POST /admin/auth/user/4/change/ HTTP/1.1" 302 0
"GET /admin/auth/user/ HTTP/1.1" 200 15245
"GET /admin/jsi18n/ HTTP/1.1" 200 17546
"GET /admin/auth/user/2/change/ HTTP/1.1" 200 24720
"GET /admin/jsi18n/ HTTP/1.1" 200 17546
"POST /admin/auth/user/2/change/ HTTP/1.1" 302 0
"GET /admin/auth/user/ HTTP/1.1" 200 15245
"GET /admin/jsi18n/ HTTP/1.1" 200 17546
"GET /admin/auth/user/3/change/ HTTP/1.1" 200 24720
"GET /admin/jsi18n/ HTTP/1.1" 200 17546
"POST /admin/auth/user/3/change/ HTTP/1.1" 302 0
"GET /admin/auth/user/ HTTP/1.1" 200 15245
"GET /admin/jsi18n/ HTTP/1.1" 200 17546
"GET /admin/auth/user/4/change/ HTTP/1.1" 200 24720
"GET /admin/jsi18n/ HTTP/1.1" 200 17546
"POST /admin/auth/user/4/change/ HTTP/1.1" 302 0
"GET /admin/auth/user/ HTTP/1.1" 200 15245
"GET /admin/jsi18n/ HTTP/1.1" 200 17546
"POST /admin/logout/ HTTP/1.1" 200 3817
"GET /admin/ HTTP/1.1" 302 0
"GET /admin/login/?next=/admin/ HTTP/1.1" 200 4359
"POST /admin/login/?next=/admin/ HTTP/1.1" 302 0
"GET /admin/ HTTP/1.1" 200 6113
"GET /admin/hw1app/order/ HTTP/1.1" 200 7583
"GET /admin/hw1app/client/ HTTP/1.1" 200 7639
"GET /admin/hw1app/client/1/change/ HTTP/1.1" 200 10468
"GET /admin/jsi18n/ HTTP/1.1" 200 17546
"GET /admin/hw1app/client/ HTTP/1.1" 200 7639
"POST /admin/logout/ HTTP/1.1" 200 3817
"GET /admin/ HTTP/1.1" 302 0
"GET /admin/login/?next=/admin/ HTTP/1.1" 200 4359
"POST /admin/login/?next=/admin/ HTTP/1.1" 302 0
"GET /admin/ HTTP/1.1" 200 6315
"GET /admin/hw1app/goods/ HTTP/1.1" 200 8639
D:\GB\HTML CSS\Django\hw1\hw1app\admin.py changed, reloading.
Watching for file changes with StatReloader
D:\GB\HTML CSS\Django\hw1\hw1app\admin.py changed, reloading.
Watching for file changes with StatReloader
Invalid HTTP_HOST header: 'download.jetbrains.com'. You may need to add 'download.jetbrains.com' to ALLOWED_HOSTS.
Traceback (most recent call last):
  File "D:\GB\HTML CSS\Django\venv\Lib\site-packages\django\core\handlers\exception.py", line 55, in inner
    response = get_response(request)
               ^^^^^^^^^^^^^^^^^^^^^
  File "D:\GB\HTML CSS\Django\venv\Lib\site-packages\django\utils\deprecation.py", line 133, in __call__
    response = self.process_request(request)
               ^^^^^^^^^^^^^^^^^^^^^^^^^^^^^
  File "D:\GB\HTML CSS\Django\venv\Lib\site-packages\django\middleware\common.py", line 48, in process_request
    host = request.get_host()
           ^^^^^^^^^^^^^^^^^^
  File "D:\GB\HTML CSS\Django\venv\Lib\site-packages\django\http\request.py", line 151, in get_host
    raise DisallowedHost(msg)
django.core.exceptions.DisallowedHost: Invalid HTTP_HOST header: 'download.jetbrains.com'. You may need to add 'download.jetbrains.com' to ALLOWED_HOSTS.
Bad Request: /download.jetbrains.com:443
"CONNECT download.jetbrains.com:443 HTTP/1.1" 400 67350
D:\GB\HTML CSS\Django\hw1\hw1app\admin.py changed, reloading.
Watching for file changes with StatReloader
"GET /admin/hw1app/goods/ HTTP/1.1" 200 8639
"GET /admin/ HTTP/1.1" 200 6315
"GET /admin/hw1app/goods/ HTTP/1.1" 200 8639
"GET /admin/hw1app/goods/10/change/ HTTP/1.1" 200 11961
"GET /admin/jsi18n/ HTTP/1.1" 200 17546
"GET /admin/hw1app/goods/ HTTP/1.1" 200 8639
"GET /admin/hw1app/goods/10/change/ HTTP/1.1" 200 11961
"GET /admin/jsi18n/ HTTP/1.1" 200 17546
"POST /admin/hw1app/goods/10/change/ HTTP/1.1" 302 0
"GET /admin/hw1app/goods/ HTTP/1.1" 200 8852
"POST /admin/logout/ HTTP/1.1" 200 3817
"GET /admin/ HTTP/1.1" 302 0
"GET /admin/login/?next=/admin/ HTTP/1.1" 200 4359
"POST /admin/login/?next=/admin/ HTTP/1.1" 200 4626
"POST /admin/login/?next=/admin/ HTTP/1.1" 302 0
"GET /admin/ HTTP/1.1" 200 6113
Invalid HTTP_HOST header: 'download.jetbrains.com'. You may need to add 'download.jetbrains.com' to ALLOWED_HOSTS.
Traceback (most recent call last):
  File "D:\GB\HTML CSS\Django\venv\Lib\site-packages\django\core\handlers\exception.py", line 55, in inner
    response = get_response(request)
               ^^^^^^^^^^^^^^^^^^^^^
  File "D:\GB\HTML CSS\Django\venv\Lib\site-packages\django\utils\deprecation.py", line 133, in __call__
    response = self.process_request(request)
               ^^^^^^^^^^^^^^^^^^^^^^^^^^^^^
  File "D:\GB\HTML CSS\Django\venv\Lib\site-packages\django\middleware\common.py", line 48, in process_request
    host = request.get_host()
           ^^^^^^^^^^^^^^^^^^
  File "D:\GB\HTML CSS\Django\venv\Lib\site-packages\django\http\request.py", line 151, in get_host
    raise DisallowedHost(msg)
django.core.exceptions.DisallowedHost: Invalid HTTP_HOST header: 'download.jetbrains.com'. You may need to add 'download.jetbrains.com' to ALLOWED_HOSTS.
Bad Request: /download.jetbrains.com:443
"CONNECT download.jetbrains.com:443 HTTP/1.1" 400 67350
"GET /admin/hw1app/goods/ HTTP/1.1" 200 8308
"GET /admin/hw1app/goods/10/change/ HTTP/1.1" 200 10775
"GET /admin/jsi18n/ HTTP/1.1" 200 17546
"GET /admin/hw1app/goods/ HTTP/1.1" 200 8308
"GET /admin/hw1app/ HTTP/1.1" 200 6079
"GET /admin/hw1app/goods/ HTTP/1.1" 200 8308
"GET /admin/hw1app/goods/3/change/ HTTP/1.1" 200 10830
"GET /admin/jsi18n/ HTTP/1.1" 200 17546
"GET /admin/hw1app/goods/3/history/ HTTP/1.1" 200 6439
"GET /admin/hw1app/goods/3/change/ HTTP/1.1" 200 10830
D:\GB\HTML CSS\Django\hw1\hw1app\admin.py changed, reloading.
Watching for file changes with StatReloader
"GET /admin/hw1app/goods/3/change/ HTTP/1.1" 200 10830
"GET /admin/jsi18n/ HTTP/1.1" 200 17546
"GET /admin/hw1app/goods/ HTTP/1.1" 200 10997
"GET /static/admin/img/sorting-icons.svg HTTP/1.1" 200 1097
"GET /admin/hw1app/goods/?o=0.2 HTTP/1.1" 200 11215
"GET /admin/hw1app/goods/?o=0.-2 HTTP/1.1" 200 11229
"GET /admin/hw1app/goods/?o=0.2 HTTP/1.1" 200 11215
"GET /admin/hw1app/goods/?o=0.-2 HTTP/1.1" 200 11229
"GET /admin/hw1app/goods/?o=0.2 HTTP/1.1" 200 11215
"GET /admin/hw1app/goods/?o=-0.2 HTTP/1.1" 200 11229
"GET /admin/hw1app/goods/?o=0.2 HTTP/1.1" 200 11215
Invalid HTTP_HOST header: 'download.jetbrains.com'. You may need to add 'download.jetbrains.com' to ALLOWED_HOSTS.
Traceback (most recent call last):
  File "D:\GB\HTML CSS\Django\venv\Lib\site-packages\django\core\handlers\exception.py", line 55, in inner
    response = get_response(request)
               ^^^^^^^^^^^^^^^^^^^^^
  File "D:\GB\HTML CSS\Django\venv\Lib\site-packages\django\utils\deprecation.py", line 133, in __call__
    response = self.process_request(request)
               ^^^^^^^^^^^^^^^^^^^^^^^^^^^^^
  File "D:\GB\HTML CSS\Django\venv\Lib\site-packages\django\middleware\common.py", line 48, in process_request
    host = request.get_host()
           ^^^^^^^^^^^^^^^^^^
  File "D:\GB\HTML CSS\Django\venv\Lib\site-packages\django\http\request.py", line 151, in get_host
    raise DisallowedHost(msg)
django.core.exceptions.DisallowedHost: Invalid HTTP_HOST header: 'download.jetbrains.com'. You may need to add 'download.jetbrains.com' to ALLOWED_HOSTS.
Bad Request: /download.jetbrains.com:443
"CONNECT download.jetbrains.com:443 HTTP/1.1" 400 67350
"GET /admin/hw1app/goods/ HTTP/1.1" 200 10997
"GET /admin/hw1app/goods/10/change/ HTTP/1.1" 200 10775
"GET /admin/jsi18n/ HTTP/1.1" 200 17546
"GET /admin/hw1app/goods/ HTTP/1.1" 200 10997
D:\GB\HTML CSS\Django\hw1\hw1app\admin.py changed, reloading.
Watching for file changes with StatReloader
Invalid HTTP_HOST header: 'download.jetbrains.com'. You may need to add 'download.jetbrains.com' to ALLOWED_HOSTS.
Traceback (most recent call last):
  File "D:\GB\HTML CSS\Django\venv\Lib\site-packages\django\core\handlers\exception.py", line 55, in inner
    response = get_response(request)
               ^^^^^^^^^^^^^^^^^^^^^
  File "D:\GB\HTML CSS\Django\venv\Lib\site-packages\django\utils\deprecation.py", line 133, in __call__
    response = self.process_request(request)
               ^^^^^^^^^^^^^^^^^^^^^^^^^^^^^
  File "D:\GB\HTML CSS\Django\venv\Lib\site-packages\django\middleware\common.py", line 48, in process_request
    host = request.get_host()
           ^^^^^^^^^^^^^^^^^^
  File "D:\GB\HTML CSS\Django\venv\Lib\site-packages\django\http\request.py", line 151, in get_host
    raise DisallowedHost(msg)
django.core.exceptions.DisallowedHost: Invalid HTTP_HOST header: 'download.jetbrains.com'. You may need to add 'download.jetbrains.com' to ALLOWED_HOSTS.
Bad Request: /download.jetbrains.com:443
"CONNECT download.jetbrains.com:443 HTTP/1.1" 400 67350
D:\GB\HTML CSS\Django\hw1\hw1app\admin.py changed, reloading.
Watching for file changes with StatReloader
"GET /admin/hw1app/goods/ HTTP/1.1" 200 10305
"GET /admin/hw1app/goods/?p=2 HTTP/1.1" 200 9909
D:\GB\HTML CSS\Django\hw1\hw1app\admin.py changed, reloading.
Watching for file changes with StatReloader
"GET /admin/hw1app/goods/?p=2 HTTP/1.1" 200 10238
"GET /admin/hw1app/goods/?p=1 HTTP/1.1" 200 10764
Internal Server Error: /admin/hw1app/goods/
Traceback (most recent call last):
  File "D:\GB\HTML CSS\Django\venv\Lib\site-packages\django\core\handlers\exception.py", line 55, in inner
    response = get_response(request)
               ^^^^^^^^^^^^^^^^^^^^^
  File "D:\GB\HTML CSS\Django\venv\Lib\site-packages\django\core\handlers\base.py", line 197, in _get_response
    response = wrapped_callback(request, *callback_args, **callback_kwargs)
               ^^^^^^^^^^^^^^^^^^^^^^^^^^^^^^^^^^^^^^^^^^^^^^^^^^^^^^^^^^^^
  File "D:\GB\HTML CSS\Django\venv\Lib\site-packages\django\contrib\admin\options.py", line 716, in wrapper
    return self.admin_site.admin_view(view)(*args, **kwargs)
           ^^^^^^^^^^^^^^^^^^^^^^^^^^^^^^^^^^^^^^^^^^^^^^^^^
  File "D:\GB\HTML CSS\Django\venv\Lib\site-packages\django\utils\decorators.py", line 188, in _view_wrapper
    result = _process_exception(request, e)
             ^^^^^^^^^^^^^^^^^^^^^^^^^^^^^^
  File "D:\GB\HTML CSS\Django\venv\Lib\site-packages\django\utils\decorators.py", line 186, in _view_wrapper
    response = view_func(request, *args, **kwargs)
               ^^^^^^^^^^^^^^^^^^^^^^^^^^^^^^^^^^^
  File "D:\GB\HTML CSS\Django\venv\Lib\site-packages\django\views\decorators\cache.py", line 80, in _view_wrapper
    response = view_func(request, *args, **kwargs)
               ^^^^^^^^^^^^^^^^^^^^^^^^^^^^^^^^^^^
  File "D:\GB\HTML CSS\Django\venv\Lib\site-packages\django\contrib\admin\sites.py", line 240, in inner
    return view(request, *args, **kwargs)
           ^^^^^^^^^^^^^^^^^^^^^^^^^^^^^^
  File "D:\GB\HTML CSS\Django\venv\Lib\site-packages\django\utils\decorators.py", line 48, in _wrapper
    return bound_method(*args, **kwargs)
           ^^^^^^^^^^^^^^^^^^^^^^^^^^^^^
  File "D:\GB\HTML CSS\Django\venv\Lib\site-packages\django\utils\decorators.py", line 188, in _view_wrapper
    result = _process_exception(request, e)
             ^^^^^^^^^^^^^^^^^^^^^^^^^^^^^^
  File "D:\GB\HTML CSS\Django\venv\Lib\site-packages\django\utils\decorators.py", line 186, in _view_wrapper
    response = view_func(request, *args, **kwargs)
               ^^^^^^^^^^^^^^^^^^^^^^^^^^^^^^^^^^^
  File "D:\GB\HTML CSS\Django\venv\Lib\site-packages\django\contrib\admin\options.py", line 1985, in changelist_view
    cl = self.get_changelist_instance(request)
         ^^^^^^^^^^^^^^^^^^^^^^^^^^^^^^^^^^^^^
  File "D:\GB\HTML CSS\Django\venv\Lib\site-packages\django\contrib\admin\options.py", line 864, in get_changelist_instance
    return ChangeList(
           ^^^^^^^^^^^
  File "D:\GB\HTML CSS\Django\venv\Lib\site-packages\django\contrib\admin\views\main.py", line 144, in __init__
    self.queryset = self.get_queryset(request)
                    ^^^^^^^^^^^^^^^^^^^^^^^^^^
  File "D:\GB\HTML CSS\Django\venv\Lib\site-packages\django\contrib\admin\views\main.py", line 577, in get_queryset
    qs, search_may_have_duplicates = self.model_admin.get_search_results(
                                     ^^^^^^^^^^^^^^^^^^^^^^^^^^^^^^^^^^^^
  File "D:\GB\HTML CSS\Django\venv\Lib\site-packages\django\contrib\admin\options.py", line 1187, in get_search_results
    queryset = queryset.filter(models.Q.create(term_queries))
               ^^^^^^^^^^^^^^^^^^^^^^^^^^^^^^^^^^^^^^^^^^^^^^
  File "D:\GB\HTML CSS\Django\venv\Lib\site-packages\django\db\models\query.py", line 1476, in filter
    return self._filter_or_exclude(False, args, kwargs)
           ^^^^^^^^^^^^^^^^^^^^^^^^^^^^^^^^^^^^^^^^^^^^
  File "D:\GB\HTML CSS\Django\venv\Lib\site-packages\django\db\models\query.py", line 1494, in _filter_or_exclude
    clone._filter_or_exclude_inplace(negate, args, kwargs)
  File "D:\GB\HTML CSS\Django\venv\Lib\site-packages\django\db\models\query.py", line 1501, in _filter_or_exclude_inplace
    self._query.add_q(Q(*args, **kwargs))
  File "D:\GB\HTML CSS\Django\venv\Lib\site-packages\django\db\models\sql\query.py", line 1613, in add_q
    clause, _ = self._add_q(q_object, self.used_aliases)
                ^^^^^^^^^^^^^^^^^^^^^^^^^^^^^^^^^^^^^^^^
  File "D:\GB\HTML CSS\Django\venv\Lib\site-packages\django\db\models\sql\query.py", line 1645, in _add_q
    child_clause, needed_inner = self.build_filter(
                                 ^^^^^^^^^^^^^^^^^^
  File "D:\GB\HTML CSS\Django\venv\Lib\site-packages\django\db\models\sql\query.py", line 1472, in build_filter
    return self._add_q(
           ^^^^^^^^^^^^
  File "D:\GB\HTML CSS\Django\venv\Lib\site-packages\django\db\models\sql\query.py", line 1645, in _add_q
    child_clause, needed_inner = self.build_filter(
                                 ^^^^^^^^^^^^^^^^^^
  File "D:\GB\HTML CSS\Django\venv\Lib\site-packages\django\db\models\sql\query.py", line 1472, in build_filter
    return self._add_q(
           ^^^^^^^^^^^^
  File "D:\GB\HTML CSS\Django\venv\Lib\site-packages\django\db\models\sql\query.py", line 1645, in _add_q
    child_clause, needed_inner = self.build_filter(
                                 ^^^^^^^^^^^^^^^^^^
  File "D:\GB\HTML CSS\Django\venv\Lib\site-packages\django\db\models\sql\query.py", line 1495, in build_filter
    lookups, parts, reffed_expression = self.solve_lookup_type(arg, summarize)
                                        ^^^^^^^^^^^^^^^^^^^^^^^^^^^^^^^^^^^^^^
  File "D:\GB\HTML CSS\Django\venv\Lib\site-packages\django\db\models\sql\query.py", line 1307, in solve_lookup_type
    _, field, _, lookup_parts = self.names_to_path(lookup_splitted, self.get_meta())
                                ^^^^^^^^^^^^^^^^^^^^^^^^^^^^^^^^^^^^^^^^^^^^^^^^^^^^
  File "D:\GB\HTML CSS\Django\venv\Lib\site-packages\django\db\models\sql\query.py", line 1772, in names_to_path
    raise FieldError(
django.core.exceptions.FieldError: Cannot resolve keyword 'name' into field. Choices are: date_of_add, description, id, image, order, price, quantity, title
"GET /admin/hw1app/goods/?q=1 HTTP/1.1" 500 194131
"GET /admin/hw1app/goods/?p=1 HTTP/1.1" 200 10764
"GET /admin/hw1app/goods/?p=2 HTTP/1.1" 200 10238
D:\GB\HTML CSS\Django\hw1\hw1app\admin.py changed, reloading.
Watching for file changes with StatReloader
"GET /admin/hw1app/goods/?p=2 HTTP/1.1" 200 10238
"GET /admin/hw1app/goods/?q=1 HTTP/1.1" 200 10510
"GET /admin/hw1app/goods/? HTTP/1.1" 200 10634
"GET /admin/hw1app/goods/?q=%D1%88%D0%B5%D1%80%D1%81%D1%82%D1%8C HTTP/1.1" 200 7683
"GET /admin/hw1app/goods/?q=%D1%88%D0%B5%D1%80%D1%81 HTTP/1.1" 200 7679
"GET /admin/hw1app/goods/?q=%D1%88%D0%B5%D1%80 HTTP/1.1" 200 7677
"GET /admin/hw1app/goods/? HTTP/1.1" 200 10634
"GET /admin/hw1app/goods/?p=2 HTTP/1.1" 200 10238
"GET /admin/hw1app/goods/?q=%D0%A8%D0%B5%D1%80%D1%81%D1%82%D1%8C HTTP/1.1" 200 10785
Invalid HTTP_HOST header: 'download.jetbrains.com'. You may need to add 'download.jetbrains.com' to ALLOWED_HOSTS.
Traceback (most recent call last):
  File "D:\GB\HTML CSS\Django\venv\Lib\site-packages\django\core\handlers\exception.py", line 55, in inner
    response = get_response(request)
               ^^^^^^^^^^^^^^^^^^^^^
  File "D:\GB\HTML CSS\Django\venv\Lib\site-packages\django\utils\deprecation.py", line 133, in __call__
    response = self.process_request(request)
               ^^^^^^^^^^^^^^^^^^^^^^^^^^^^^
  File "D:\GB\HTML CSS\Django\venv\Lib\site-packages\django\middleware\common.py", line 48, in process_request
    host = request.get_host()
           ^^^^^^^^^^^^^^^^^^
  File "D:\GB\HTML CSS\Django\venv\Lib\site-packages\django\http\request.py", line 151, in get_host
    raise DisallowedHost(msg)
django.core.exceptions.DisallowedHost: Invalid HTTP_HOST header: 'download.jetbrains.com'. You may need to add 'download.jetbrains.com' to ALLOWED_HOSTS.
Bad Request: /download.jetbrains.com:443
"CONNECT download.jetbrains.com:443 HTTP/1.1" 400 67350
Invalid HTTP_HOST header: 'download.jetbrains.com'. You may need to add 'download.jetbrains.com' to ALLOWED_HOSTS.
Traceback (most recent call last):
  File "D:\GB\HTML CSS\Django\venv\Lib\site-packages\django\core\handlers\exception.py", line 55, in inner
    response = get_response(request)
               ^^^^^^^^^^^^^^^^^^^^^
  File "D:\GB\HTML CSS\Django\venv\Lib\site-packages\django\utils\deprecation.py", line 133, in __call__
    response = self.process_request(request)
               ^^^^^^^^^^^^^^^^^^^^^^^^^^^^^
  File "D:\GB\HTML CSS\Django\venv\Lib\site-packages\django\middleware\common.py", line 48, in process_request
    host = request.get_host()
           ^^^^^^^^^^^^^^^^^^
  File "D:\GB\HTML CSS\Django\venv\Lib\site-packages\django\http\request.py", line 151, in get_host
    raise DisallowedHost(msg)
django.core.exceptions.DisallowedHost: Invalid HTTP_HOST header: 'download.jetbrains.com'. You may need to add 'download.jetbrains.com' to ALLOWED_HOSTS.
Bad Request: /download.jetbrains.com:443
"CONNECT download.jetbrains.com:443 HTTP/1.1" 400 67350
D:\GB\HTML CSS\Django\hw1\hw1app\admin.py changed, reloading.
Watching for file changes with StatReloader
D:\GB\HTML CSS\Django\hw1\hw1app\admin.py changed, reloading.
Watching for file changes with StatReloader
D:\GB\HTML CSS\Django\hw1\hw1app\admin.py changed, reloading.
Watching for file changes with StatReloader
D:\GB\HTML CSS\Django\hw1\hw1app\admin.py changed, reloading.
Watching for file changes with StatReloader
D:\GB\HTML CSS\Django\hw1\hw1app\admin.py changed, reloading.
Watching for file changes with StatReloader
"GET / HTTP/1.1" 200 90
"GET /admin/ HTTP/1.1" 200 6113
"GET /admin/hw1app/goods/ HTTP/1.1" 200 10634
"GET /admin/hw1app/goods/?all= HTTP/1.1" 200 11670
"GET /admin/hw1app/goods/ HTTP/1.1" 200 10634
"GET /admin/hw1app/goods/10/change/ HTTP/1.1" 200 10801
"GET /admin/jsi18n/ HTTP/1.1" 200 17546
"GET /static/admin/js/collapse.js HTTP/1.1" 200 1803
D:\GB\HTML CSS\Django\hw1\hw1app\admin.py changed, reloading.
Watching for file changes with StatReloader
"GET /admin/hw1app/goods/10/change/ HTTP/1.1" 200 10797
"GET /admin/jsi18n/ HTTP/1.1" 200 17546
D:\GB\HTML CSS\Django\hw1\hw1app\admin.py changed, reloading.
Watching for file changes with StatReloader
"GET /admin/hw1app/goods/10/change/ HTTP/1.1" 200 10801
"GET /admin/jsi18n/ HTTP/1.1" 200 17546
"GET /admin/hw1app/goods/10/change/ HTTP/1.1" 200 10801
"GET /admin/jsi18n/ HTTP/1.1" 200 17546
Invalid HTTP_HOST header: 'download.jetbrains.com'. You may need to add 'download.jetbrains.com' to ALLOWED_HOSTS.
Traceback (most recent call last):
  File "D:\GB\HTML CSS\Django\venv\Lib\site-packages\django\core\handlers\exception.py", line 55, in inner
    response = get_response(request)
               ^^^^^^^^^^^^^^^^^^^^^
  File "D:\GB\HTML CSS\Django\venv\Lib\site-packages\django\utils\deprecation.py", line 133, in __call__
    response = self.process_request(request)
               ^^^^^^^^^^^^^^^^^^^^^^^^^^^^^
  File "D:\GB\HTML CSS\Django\venv\Lib\site-packages\django\middleware\common.py", line 48, in process_request
    host = request.get_host()
           ^^^^^^^^^^^^^^^^^^
  File "D:\GB\HTML CSS\Django\venv\Lib\site-packages\django\http\request.py", line 151, in get_host
    raise DisallowedHost(msg)
django.core.exceptions.DisallowedHost: Invalid HTTP_HOST header: 'download.jetbrains.com'. You may need to add 'download.jetbrains.com' to ALLOWED_HOSTS.
Bad Request: /download.jetbrains.com:443
"CONNECT download.jetbrains.com:443 HTTP/1.1" 400 67350
Invalid HTTP_HOST header: 'schemastore.org'. You may need to add 'schemastore.org' to ALLOWED_HOSTS.
Traceback (most recent call last):
  File "D:\GB\HTML CSS\Django\venv\Lib\site-packages\django\core\handlers\exception.py", line 55, in inner
    response = get_response(request)
               ^^^^^^^^^^^^^^^^^^^^^
  File "D:\GB\HTML CSS\Django\venv\Lib\site-packages\django\utils\deprecation.py", line 133, in __call__
    response = self.process_request(request)
               ^^^^^^^^^^^^^^^^^^^^^^^^^^^^^
  File "D:\GB\HTML CSS\Django\venv\Lib\site-packages\django\middleware\common.py", line 48, in process_request
    host = request.get_host()
           ^^^^^^^^^^^^^^^^^^
  File "D:\GB\HTML CSS\Django\venv\Lib\site-packages\django\http\request.py", line 151, in get_host
    raise DisallowedHost(msg)
django.core.exceptions.DisallowedHost: Invalid HTTP_HOST header: 'schemastore.org'. You may need to add 'schemastore.org' to ALLOWED_HOSTS.
Bad Request: /schemastore.org:443
"CONNECT schemastore.org:443 HTTP/1.1" 400 67168
D:\GB\HTML CSS\Django\hw1\hw1app\admin.py changed, reloading.
Watching for file changes with StatReloader
D:\GB\HTML CSS\Django\hw1\hw1app\admin.py changed, reloading.
Watching for file changes with StatReloader
Invalid HTTP_HOST header: 'download.jetbrains.com'. You may need to add 'download.jetbrains.com' to ALLOWED_HOSTS.
Traceback (most recent call last):
  File "D:\GB\HTML CSS\Django\venv\Lib\site-packages\django\core\handlers\exception.py", line 55, in inner
    response = get_response(request)
               ^^^^^^^^^^^^^^^^^^^^^
  File "D:\GB\HTML CSS\Django\venv\Lib\site-packages\django\utils\deprecation.py", line 133, in __call__
    response = self.process_request(request)
               ^^^^^^^^^^^^^^^^^^^^^^^^^^^^^
  File "D:\GB\HTML CSS\Django\venv\Lib\site-packages\django\middleware\common.py", line 48, in process_request
    host = request.get_host()
           ^^^^^^^^^^^^^^^^^^
  File "D:\GB\HTML CSS\Django\venv\Lib\site-packages\django\http\request.py", line 151, in get_host
    raise DisallowedHost(msg)
django.core.exceptions.DisallowedHost: Invalid HTTP_HOST header: 'download.jetbrains.com'. You may need to add 'download.jetbrains.com' to ALLOWED_HOSTS.
Bad Request: /download.jetbrains.com:443
"CONNECT download.jetbrains.com:443 HTTP/1.1" 400 67350
D:\GB\HTML CSS\Django\hw1\hw1app\admin.py changed, reloading.
Watching for file changes with StatReloader
D:\GB\HTML CSS\Django\hw1\hw1app\admin.py changed, reloading.
Watching for file changes with StatReloader
D:\GB\HTML CSS\Django\hw1\hw1app\admin.py changed, reloading.
Watching for file changes with StatReloader
D:\GB\HTML CSS\Django\hw1\hw1app\admin.py changed, reloading.
Watching for file changes with StatReloader
D:\GB\HTML CSS\Django\hw1\hw1app\admin.py changed, reloading.
Watching for file changes with StatReloader
"GET /admin/hw1app/goods/10/change/ HTTP/1.1" 200 10801
"GET /admin/jsi18n/ HTTP/1.1" 200 17546
"POST /admin/logout/ HTTP/1.1" 200 3817
"GET /admin/ HTTP/1.1" 302 0
"GET /admin/login/?next=/admin/ HTTP/1.1" 200 4359
"POST /admin/login/?next=/admin/ HTTP/1.1" 302 0
"GET /admin/ HTTP/1.1" 200 11220
"GET /admin/hw1app/goods/ HTTP/1.1" 200 14449
"GET /admin/jsi18n/ HTTP/1.1" 200 17546
"GET /admin/hw1app/goods/ HTTP/1.1" 200 14449
"GET /admin/jsi18n/ HTTP/1.1" 200 17546
"GET /admin/hw1app/goods/10/change/ HTTP/1.1" 200 12915
"GET /admin/jsi18n/ HTTP/1.1" 200 17546
"GET /admin/hw1app/goods/ HTTP/1.1" 200 14449
"GET /admin/jsi18n/ HTTP/1.1" 200 17546
Invalid HTTP_HOST header: 'download.jetbrains.com'. You may need to add 'download.jetbrains.com' to ALLOWED_HOSTS.
Traceback (most recent call last):
  File "D:\GB\HTML CSS\Django\venv\Lib\site-packages\django\core\handlers\exception.py", line 55, in inner
    response = get_response(request)
               ^^^^^^^^^^^^^^^^^^^^^
  File "D:\GB\HTML CSS\Django\venv\Lib\site-packages\django\utils\deprecation.py", line 133, in __call__
    response = self.process_request(request)
               ^^^^^^^^^^^^^^^^^^^^^^^^^^^^^
  File "D:\GB\HTML CSS\Django\venv\Lib\site-packages\django\middleware\common.py", line 48, in process_request
    host = request.get_host()
           ^^^^^^^^^^^^^^^^^^
  File "D:\GB\HTML CSS\Django\venv\Lib\site-packages\django\http\request.py", line 151, in get_host
    raise DisallowedHost(msg)
django.core.exceptions.DisallowedHost: Invalid HTTP_HOST header: 'download.jetbrains.com'. You may need to add 'download.jetbrains.com' to ALLOWED_HOSTS.
Bad Request: /download.jetbrains.com:443
"CONNECT download.jetbrains.com:443 HTTP/1.1" 400 67350
D:\GB\HTML CSS\Django\hw1\hw1app\admin.py changed, reloading.
Watching for file changes with StatReloader
D:\GB\HTML CSS\Django\hw1\hw1app\admin.py changed, reloading.
Watching for file changes with StatReloader
"GET /admin/hw1app/goods/ HTTP/1.1" 200 14449
"GET /admin/jsi18n/ HTTP/1.1" 200 17546
"GET /admin/hw1app/goods/ HTTP/1.1" 200 14449
"GET /admin/jsi18n/ HTTP/1.1" 200 17546
"GET /admin/hw1app/goods/ HTTP/1.1" 200 14449
"GET /admin/jsi18n/ HTTP/1.1" 200 17546
D:\GB\HTML CSS\Django\hw1\hw1app\admin.py changed, reloading.
Watching for file changes with StatReloader
"GET /admin/hw1app/goods/ HTTP/1.1" 200 14600
"GET /admin/jsi18n/ HTTP/1.1" 200 17546
"POST /admin/hw1app/goods/ HTTP/1.1" 302 0
"GET /admin/hw1app/goods/ HTTP/1.1" 200 14600
"GET /admin/jsi18n/ HTTP/1.1" 200 17546
"POST /admin/hw1app/goods/ HTTP/1.1" 302 0
"GET /admin/hw1app/goods/ HTTP/1.1" 200 14632
"GET /admin/jsi18n/ HTTP/1.1" 200 17546
Invalid HTTP_HOST header: 'download.jetbrains.com'. You may need to add 'download.jetbrains.com' to ALLOWED_HOSTS.
Traceback (most recent call last):
  File "D:\GB\HTML CSS\Django\venv\Lib\site-packages\django\core\handlers\exception.py", line 55, in inner
    response = get_response(request)
               ^^^^^^^^^^^^^^^^^^^^^
  File "D:\GB\HTML CSS\Django\venv\Lib\site-packages\django\utils\deprecation.py", line 133, in __call__
    response = self.process_request(request)
               ^^^^^^^^^^^^^^^^^^^^^^^^^^^^^
  File "D:\GB\HTML CSS\Django\venv\Lib\site-packages\django\middleware\common.py", line 48, in process_request
    host = request.get_host()
           ^^^^^^^^^^^^^^^^^^
  File "D:\GB\HTML CSS\Django\venv\Lib\site-packages\django\http\request.py", line 151, in get_host
    raise DisallowedHost(msg)
django.core.exceptions.DisallowedHost: Invalid HTTP_HOST header: 'download.jetbrains.com'. You may need to add 'download.jetbrains.com' to ALLOWED_HOSTS.
Bad Request: /download.jetbrains.com:443
"CONNECT download.jetbrains.com:443 HTTP/1.1" 400 67350
D:\GB\HTML CSS\Django\hw1\hw1app\admin.py changed, reloading.
Watching for file changes with StatReloader
D:\GB\HTML CSS\Django\hw1\hw1app\admin.py changed, reloading.
Watching for file changes with StatReloader
D:\GB\HTML CSS\Django\hw1\hw1app\admin.py changed, reloading.
Watching for file changes with StatReloader
"GET /admin/hw1app/goods/ HTTP/1.1" 200 14713
"GET /admin/jsi18n/ HTTP/1.1" 200 17546
"POST /admin/hw1app/goods/ HTTP/1.1" 302 0
"GET /admin/hw1app/goods/ HTTP/1.1" 200 14744
"GET /admin/jsi18n/ HTTP/1.1" 200 17546
"POST /admin/hw1app/goods/ HTTP/1.1" 302 0
"GET /admin/hw1app/goods/ HTTP/1.1" 200 14744
"GET /admin/jsi18n/ HTTP/1.1" 200 17546
D:\GB\HTML CSS\Django\hw1\hw1app\admin.py changed, reloading.
Watching for file changes with StatReloader
"GET /admin/hw1app/goods/ HTTP/1.1" 200 14717
"GET /admin/jsi18n/ HTTP/1.1" 200 17546
Internal Server Error: /admin/hw1app/goods/
Traceback (most recent call last):
  File "D:\GB\HTML CSS\Django\venv\Lib\site-packages\django\core\handlers\exception.py", line 55, in inner
    response = get_response(request)
               ^^^^^^^^^^^^^^^^^^^^^
  File "D:\GB\HTML CSS\Django\venv\Lib\site-packages\django\core\handlers\base.py", line 197, in _get_response
    response = wrapped_callback(request, *callback_args, **callback_kwargs)
               ^^^^^^^^^^^^^^^^^^^^^^^^^^^^^^^^^^^^^^^^^^^^^^^^^^^^^^^^^^^^
  File "D:\GB\HTML CSS\Django\venv\Lib\site-packages\django\contrib\admin\options.py", line 716, in wrapper
    return self.admin_site.admin_view(view)(*args, **kwargs)
           ^^^^^^^^^^^^^^^^^^^^^^^^^^^^^^^^^^^^^^^^^^^^^^^^^
  File "D:\GB\HTML CSS\Django\venv\Lib\site-packages\django\utils\decorators.py", line 188, in _view_wrapper
    result = _process_exception(request, e)
             ^^^^^^^^^^^^^^^^^^^^^^^^^^^^^^
  File "D:\GB\HTML CSS\Django\venv\Lib\site-packages\django\utils\decorators.py", line 186, in _view_wrapper
    response = view_func(request, *args, **kwargs)
               ^^^^^^^^^^^^^^^^^^^^^^^^^^^^^^^^^^^
  File "D:\GB\HTML CSS\Django\venv\Lib\site-packages\django\views\decorators\cache.py", line 80, in _view_wrapper
    response = view_func(request, *args, **kwargs)
               ^^^^^^^^^^^^^^^^^^^^^^^^^^^^^^^^^^^
  File "D:\GB\HTML CSS\Django\venv\Lib\site-packages\django\contrib\admin\sites.py", line 240, in inner
    return view(request, *args, **kwargs)
           ^^^^^^^^^^^^^^^^^^^^^^^^^^^^^^
  File "D:\GB\HTML CSS\Django\venv\Lib\site-packages\django\utils\decorators.py", line 48, in _wrapper
    return bound_method(*args, **kwargs)
           ^^^^^^^^^^^^^^^^^^^^^^^^^^^^^
  File "D:\GB\HTML CSS\Django\venv\Lib\site-packages\django\utils\decorators.py", line 188, in _view_wrapper
    result = _process_exception(request, e)
             ^^^^^^^^^^^^^^^^^^^^^^^^^^^^^^
  File "D:\GB\HTML CSS\Django\venv\Lib\site-packages\django\utils\decorators.py", line 186, in _view_wrapper
    response = view_func(request, *args, **kwargs)
               ^^^^^^^^^^^^^^^^^^^^^^^^^^^^^^^^^^^
  File "D:\GB\HTML CSS\Django\venv\Lib\site-packages\django\contrib\admin\options.py", line 2018, in changelist_view
    response = self.response_action(
               ^^^^^^^^^^^^^^^^^^^^^
  File "D:\GB\HTML CSS\Django\venv\Lib\site-packages\django\contrib\admin\options.py", line 1650, in response_action
    response = func(self, request, queryset)
               ^^^^^^^^^^^^^^^^^^^^^^^^^^^^^
  File "D:\GB\HTML CSS\Django\hw1\hw1app\admin.py", line 16, in filter_price
    queryset.filter(price__gt=10).update(price='price'*0.85)
                                               ~~~~~~~^~~~~
TypeError: can't multiply sequence by non-int of type 'float'
"POST /admin/hw1app/goods/ HTTP/1.1" 500 118904
Invalid HTTP_HOST header: 'download.jetbrains.com'. You may need to add 'download.jetbrains.com' to ALLOWED_HOSTS.
Traceback (most recent call last):
  File "D:\GB\HTML CSS\Django\venv\Lib\site-packages\django\core\handlers\exception.py", line 55, in inner
    response = get_response(request)
               ^^^^^^^^^^^^^^^^^^^^^
  File "D:\GB\HTML CSS\Django\venv\Lib\site-packages\django\utils\deprecation.py", line 133, in __call__
    response = self.process_request(request)
               ^^^^^^^^^^^^^^^^^^^^^^^^^^^^^
  File "D:\GB\HTML CSS\Django\venv\Lib\site-packages\django\middleware\common.py", line 48, in process_request
    host = request.get_host()
           ^^^^^^^^^^^^^^^^^^
  File "D:\GB\HTML CSS\Django\venv\Lib\site-packages\django\http\request.py", line 151, in get_host
    raise DisallowedHost(msg)
django.core.exceptions.DisallowedHost: Invalid HTTP_HOST header: 'download.jetbrains.com'. You may need to add 'download.jetbrains.com' to ALLOWED_HOSTS.
Bad Request: /download.jetbrains.com:443
"CONNECT download.jetbrains.com:443 HTTP/1.1" 400 67350
D:\GB\HTML CSS\Django\hw1\hw1app\admin.py changed, reloading.
Watching for file changes with StatReloader
"GET /admin/hw1app/goods/ HTTP/1.1" 200 14717
"GET /admin/jsi18n/ HTTP/1.1" 200 17546
Internal Server Error: /admin/hw1app/goods/
Traceback (most recent call last):
  File "D:\GB\HTML CSS\Django\venv\Lib\site-packages\django\db\models\fields\__init__.py", line 1805, in to_python
    decimal_value = decimal.Decimal(value)
                    ^^^^^^^^^^^^^^^^^^^^^^
decimal.InvalidOperation: [<class 'decimal.ConversionSyntax'>]

During handling of the above exception, another exception occurred:

Traceback (most recent call last):
  File "D:\GB\HTML CSS\Django\venv\Lib\site-packages\django\core\handlers\exception.py", line 55, in inner
    response = get_response(request)
               ^^^^^^^^^^^^^^^^^^^^^
  File "D:\GB\HTML CSS\Django\venv\Lib\site-packages\django\core\handlers\base.py", line 197, in _get_response
    response = wrapped_callback(request, *callback_args, **callback_kwargs)
               ^^^^^^^^^^^^^^^^^^^^^^^^^^^^^^^^^^^^^^^^^^^^^^^^^^^^^^^^^^^^
  File "D:\GB\HTML CSS\Django\venv\Lib\site-packages\django\contrib\admin\options.py", line 716, in wrapper
    return self.admin_site.admin_view(view)(*args, **kwargs)
           ^^^^^^^^^^^^^^^^^^^^^^^^^^^^^^^^^^^^^^^^^^^^^^^^^
  File "D:\GB\HTML CSS\Django\venv\Lib\site-packages\django\utils\decorators.py", line 188, in _view_wrapper
    result = _process_exception(request, e)
             ^^^^^^^^^^^^^^^^^^^^^^^^^^^^^^
  File "D:\GB\HTML CSS\Django\venv\Lib\site-packages\django\utils\decorators.py", line 186, in _view_wrapper
    response = view_func(request, *args, **kwargs)
               ^^^^^^^^^^^^^^^^^^^^^^^^^^^^^^^^^^^
  File "D:\GB\HTML CSS\Django\venv\Lib\site-packages\django\views\decorators\cache.py", line 80, in _view_wrapper
    response = view_func(request, *args, **kwargs)
               ^^^^^^^^^^^^^^^^^^^^^^^^^^^^^^^^^^^
  File "D:\GB\HTML CSS\Django\venv\Lib\site-packages\django\contrib\admin\sites.py", line 240, in inner
    return view(request, *args, **kwargs)
           ^^^^^^^^^^^^^^^^^^^^^^^^^^^^^^
  File "D:\GB\HTML CSS\Django\venv\Lib\site-packages\django\utils\decorators.py", line 48, in _wrapper
    return bound_method(*args, **kwargs)
           ^^^^^^^^^^^^^^^^^^^^^^^^^^^^^
  File "D:\GB\HTML CSS\Django\venv\Lib\site-packages\django\utils\decorators.py", line 188, in _view_wrapper
    result = _process_exception(request, e)
             ^^^^^^^^^^^^^^^^^^^^^^^^^^^^^^
  File "D:\GB\HTML CSS\Django\venv\Lib\site-packages\django\utils\decorators.py", line 186, in _view_wrapper
    response = view_func(request, *args, **kwargs)
               ^^^^^^^^^^^^^^^^^^^^^^^^^^^^^^^^^^^
  File "D:\GB\HTML CSS\Django\venv\Lib\site-packages\django\contrib\admin\options.py", line 2018, in changelist_view
    response = self.response_action(
               ^^^^^^^^^^^^^^^^^^^^^
  File "D:\GB\HTML CSS\Django\venv\Lib\site-packages\django\contrib\admin\options.py", line 1650, in response_action
    response = func(self, request, queryset)
               ^^^^^^^^^^^^^^^^^^^^^^^^^^^^^
  File "D:\GB\HTML CSS\Django\hw1\hw1app\admin.py", line 16, in filter_price
    queryset.filter(price__gt=10).update(price='price'*5)
  File "D:\GB\HTML CSS\Django\venv\Lib\site-packages\django\db\models\query.py", line 1253, in update
    rows = query.get_compiler(self.db).execute_sql(CURSOR)
           ^^^^^^^^^^^^^^^^^^^^^^^^^^^^^^^^^^^^^^^^^^^^^^^
  File "D:\GB\HTML CSS\Django\venv\Lib\site-packages\django\db\models\sql\compiler.py", line 1990, in execute_sql
    cursor = super().execute_sql(result_type)
             ^^^^^^^^^^^^^^^^^^^^^^^^^^^^^^^^
  File "D:\GB\HTML CSS\Django\venv\Lib\site-packages\django\db\models\sql\compiler.py", line 1549, in execute_sql
    sql, params = self.as_sql()
                  ^^^^^^^^^^^^^
  File "D:\GB\HTML CSS\Django\venv\Lib\site-packages\django\db\models\sql\compiler.py", line 1953, in as_sql
    val = field.get_db_prep_save(val, connection=self.connection)
          ^^^^^^^^^^^^^^^^^^^^^^^^^^^^^^^^^^^^^^^^^^^^^^^^^^^^^^^
  File "D:\GB\HTML CSS\Django\venv\Lib\site-packages\django\db\models\fields\__init__.py", line 1824, in get_db_prep_save
    self.to_python(value), self.max_digits, self.decimal_places
    ^^^^^^^^^^^^^^^^^^^^^
  File "D:\GB\HTML CSS\Django\venv\Lib\site-packages\django\db\models\fields\__init__.py", line 1807, in to_python
    raise exceptions.ValidationError(
django.core.exceptions.ValidationError: ['Значение “pricepricepricepriceprice” должно быть десятичным числом.']
"POST /admin/hw1app/goods/ HTTP/1.1" 500 150463
D:\GB\HTML CSS\Django\hw1\hw1app\admin.py changed, reloading.
Watching for file changes with StatReloader
"GET /admin/hw1app/goods/ HTTP/1.1" 200 14717
"GET /admin/jsi18n/ HTTP/1.1" 200 17546
Internal Server Error: /admin/hw1app/goods/
Traceback (most recent call last):
  File "D:\GB\HTML CSS\Django\venv\Lib\site-packages\django\core\handlers\exception.py", line 55, in inner
    response = get_response(request)
               ^^^^^^^^^^^^^^^^^^^^^
  File "D:\GB\HTML CSS\Django\venv\Lib\site-packages\django\core\handlers\base.py", line 197, in _get_response
    response = wrapped_callback(request, *callback_args, **callback_kwargs)
               ^^^^^^^^^^^^^^^^^^^^^^^^^^^^^^^^^^^^^^^^^^^^^^^^^^^^^^^^^^^^
  File "D:\GB\HTML CSS\Django\venv\Lib\site-packages\django\contrib\admin\options.py", line 716, in wrapper
    return self.admin_site.admin_view(view)(*args, **kwargs)
           ^^^^^^^^^^^^^^^^^^^^^^^^^^^^^^^^^^^^^^^^^^^^^^^^^
  File "D:\GB\HTML CSS\Django\venv\Lib\site-packages\django\utils\decorators.py", line 188, in _view_wrapper
    result = _process_exception(request, e)
             ^^^^^^^^^^^^^^^^^^^^^^^^^^^^^^
  File "D:\GB\HTML CSS\Django\venv\Lib\site-packages\django\utils\decorators.py", line 186, in _view_wrapper
    response = view_func(request, *args, **kwargs)
               ^^^^^^^^^^^^^^^^^^^^^^^^^^^^^^^^^^^
  File "D:\GB\HTML CSS\Django\venv\Lib\site-packages\django\views\decorators\cache.py", line 80, in _view_wrapper
    response = view_func(request, *args, **kwargs)
               ^^^^^^^^^^^^^^^^^^^^^^^^^^^^^^^^^^^
  File "D:\GB\HTML CSS\Django\venv\Lib\site-packages\django\contrib\admin\sites.py", line 240, in inner
    return view(request, *args, **kwargs)
           ^^^^^^^^^^^^^^^^^^^^^^^^^^^^^^
  File "D:\GB\HTML CSS\Django\venv\Lib\site-packages\django\utils\decorators.py", line 48, in _wrapper
    return bound_method(*args, **kwargs)
           ^^^^^^^^^^^^^^^^^^^^^^^^^^^^^
  File "D:\GB\HTML CSS\Django\venv\Lib\site-packages\django\utils\decorators.py", line 188, in _view_wrapper
    result = _process_exception(request, e)
             ^^^^^^^^^^^^^^^^^^^^^^^^^^^^^^
  File "D:\GB\HTML CSS\Django\venv\Lib\site-packages\django\utils\decorators.py", line 186, in _view_wrapper
    response = view_func(request, *args, **kwargs)
               ^^^^^^^^^^^^^^^^^^^^^^^^^^^^^^^^^^^
  File "D:\GB\HTML CSS\Django\venv\Lib\site-packages\django\contrib\admin\options.py", line 2018, in changelist_view
    response = self.response_action(
               ^^^^^^^^^^^^^^^^^^^^^
  File "D:\GB\HTML CSS\Django\venv\Lib\site-packages\django\contrib\admin\options.py", line 1650, in response_action
    response = func(self, request, queryset)
               ^^^^^^^^^^^^^^^^^^^^^^^^^^^^^
TypeError: filter_price() missing 1 required positional argument: 'queryset'
"POST /admin/hw1app/goods/ HTTP/1.1" 500 114811
D:\GB\HTML CSS\Django\hw1\hw1app\admin.py changed, reloading.
Watching for file changes with StatReloader
"GET /admin/hw1app/goods/ HTTP/1.1" 200 14717
"GET /admin/jsi18n/ HTTP/1.1" 200 17546
Internal Server Error: /admin/hw1app/goods/
Traceback (most recent call last):
  File "D:\GB\HTML CSS\Django\venv\Lib\site-packages\django\core\handlers\exception.py", line 55, in inner
    response = get_response(request)
               ^^^^^^^^^^^^^^^^^^^^^
  File "D:\GB\HTML CSS\Django\venv\Lib\site-packages\django\core\handlers\base.py", line 197, in _get_response
    response = wrapped_callback(request, *callback_args, **callback_kwargs)
               ^^^^^^^^^^^^^^^^^^^^^^^^^^^^^^^^^^^^^^^^^^^^^^^^^^^^^^^^^^^^
  File "D:\GB\HTML CSS\Django\venv\Lib\site-packages\django\contrib\admin\options.py", line 716, in wrapper
    return self.admin_site.admin_view(view)(*args, **kwargs)
           ^^^^^^^^^^^^^^^^^^^^^^^^^^^^^^^^^^^^^^^^^^^^^^^^^
  File "D:\GB\HTML CSS\Django\venv\Lib\site-packages\django\utils\decorators.py", line 188, in _view_wrapper
    result = _process_exception(request, e)
             ^^^^^^^^^^^^^^^^^^^^^^^^^^^^^^
  File "D:\GB\HTML CSS\Django\venv\Lib\site-packages\django\utils\decorators.py", line 186, in _view_wrapper
    response = view_func(request, *args, **kwargs)
               ^^^^^^^^^^^^^^^^^^^^^^^^^^^^^^^^^^^
  File "D:\GB\HTML CSS\Django\venv\Lib\site-packages\django\views\decorators\cache.py", line 80, in _view_wrapper
    response = view_func(request, *args, **kwargs)
               ^^^^^^^^^^^^^^^^^^^^^^^^^^^^^^^^^^^
  File "D:\GB\HTML CSS\Django\venv\Lib\site-packages\django\contrib\admin\sites.py", line 240, in inner
    return view(request, *args, **kwargs)
           ^^^^^^^^^^^^^^^^^^^^^^^^^^^^^^
  File "D:\GB\HTML CSS\Django\venv\Lib\site-packages\django\utils\decorators.py", line 48, in _wrapper
    return bound_method(*args, **kwargs)
           ^^^^^^^^^^^^^^^^^^^^^^^^^^^^^
  File "D:\GB\HTML CSS\Django\venv\Lib\site-packages\django\utils\decorators.py", line 188, in _view_wrapper
    result = _process_exception(request, e)
             ^^^^^^^^^^^^^^^^^^^^^^^^^^^^^^
  File "D:\GB\HTML CSS\Django\venv\Lib\site-packages\django\utils\decorators.py", line 186, in _view_wrapper
    response = view_func(request, *args, **kwargs)
               ^^^^^^^^^^^^^^^^^^^^^^^^^^^^^^^^^^^
  File "D:\GB\HTML CSS\Django\venv\Lib\site-packages\django\contrib\admin\options.py", line 2018, in changelist_view
    response = self.response_action(
               ^^^^^^^^^^^^^^^^^^^^^
  File "D:\GB\HTML CSS\Django\venv\Lib\site-packages\django\contrib\admin\options.py", line 1650, in response_action
    response = func(self, request, queryset)
               ^^^^^^^^^^^^^^^^^^^^^^^^^^^^^
  File "D:\GB\HTML CSS\Django\hw1\hw1app\admin.py", line 16, in filter_price
    queryset.filter(price__gt=10).update(price=price*5)
                                               ~~~~~^~
TypeError: unsupported operand type(s) for *: 'WSGIRequest' and 'int'
"POST /admin/hw1app/goods/ HTTP/1.1" 500 118912
D:\GB\HTML CSS\Django\hw1\hw1app\admin.py changed, reloading.
Watching for file changes with StatReloader
"GET /admin/hw1app/goods/ HTTP/1.1" 200 14719
"GET /admin/jsi18n/ HTTP/1.1" 200 17546
"POST /admin/hw1app/goods/ HTTP/1.1" 302 0
"GET /admin/hw1app/goods/ HTTP/1.1" 200 14667
"GET /admin/jsi18n/ HTTP/1.1" 200 17546
Invalid HTTP_HOST header: 'download.jetbrains.com'. You may need to add 'download.jetbrains.com' to ALLOWED_HOSTS.
Traceback (most recent call last):
  File "D:\GB\HTML CSS\Django\venv\Lib\site-packages\django\core\handlers\exception.py", line 55, in inner
    response = get_response(request)
               ^^^^^^^^^^^^^^^^^^^^^
  File "D:\GB\HTML CSS\Django\venv\Lib\site-packages\django\utils\deprecation.py", line 133, in __call__
    response = self.process_request(request)
               ^^^^^^^^^^^^^^^^^^^^^^^^^^^^^
  File "D:\GB\HTML CSS\Django\venv\Lib\site-packages\django\middleware\common.py", line 48, in process_request
    host = request.get_host()
           ^^^^^^^^^^^^^^^^^^
  File "D:\GB\HTML CSS\Django\venv\Lib\site-packages\django\http\request.py", line 151, in get_host
    raise DisallowedHost(msg)
django.core.exceptions.DisallowedHost: Invalid HTTP_HOST header: 'download.jetbrains.com'. You may need to add 'download.jetbrains.com' to ALLOWED_HOSTS.
Bad Request: /download.jetbrains.com:443
"CONNECT download.jetbrains.com:443 HTTP/1.1" 400 67350
Watching for file changes with StatReloader
